Workbook

Sheet README
A1: 메모리 3사 핵심지표 — 10년 (Memory Big 3 — 10-Year Key Metrics)
A2: 2026년 8월 7일 작성 · KAIST 경영대학
A4: 탭 구성 (Tabs)
A5: 연간_10년 | B5: 2016~2025년 연간, 3사 한 페이지 비교. 연말 시가총액과 PE ratio 포함. ★ 10년 전체 채워져 있습니다.
A6: SK하이닉스_분기 | B6: 2016Q3~2026Q2 (40개 분기 칸).
A7: 삼성전자_분기 | B7: 동일.
A8: 마이크론_분기 | B8: 동일. ★ 40개 분기 전체 채워져 있습니다.
A9: 그래프_연간 | B9: 연간 데이터 그래프 6개.
A10: 그래프_분기 | B10: 분기 데이터 그래프 6개.
A12: ★ 데이터 적용 범위 (Coverage)
A13: 연간 2016~2025 | B13: 3사 모두 10년 전체 완비. 전부 감사받은 재무제표에서 직접 옮겼습니다.
A14: 분기 — 마이크론 | B14: 2016Q3~2026Q2 전체 40개 분기 완비 (SEC XBRL).
A15: 분기 — 한국 2사 | B15: 2021Q3~2026Q2 (최근 20개 분기)만 채워져 있습니다. 그 이전 20개 분기는 분기별 원자료를 검증하지 못해 비워 두었습니다 — 추측값은 넣지 않았습니다.
A16: 나머지를 채우려면 | B16: DART 전자공시의 분기보고서에서 확인해 파란색 칸에 입력하면 비율·US$ 환산·그래프가 자동으로 채워집니다. 그래프 범위는 이미 40개 분기 전체로 잡혀 있습니다.
A17: 분기 시가총액 | B17: 3사 모두 최근 20개 분기만 있습니다. 연간 시가총액은 10년 전체가 있습니다.
A19: 출처 (Sources) — 전부 1차 자료
A20: SK하이닉스 연간 | B20: 감사받은 연결재무제표 (2016·2018·2020년 보고서가 각각 2개 연도를 포함) + 2021~25년 공시 재무제표 / SEC Form 424B4.
A21: 삼성전자 연간 | B21: Samsung IR 감사받은 연결재무제표 (K-IFRS). images.samsung.com/.../[연도]_con_quarter04_{bs,soi}.pdf
A22: 마이크론 연간·분기 | B22: SEC XBRL company facts (10-K/10-Q), CIK 0000723125. 회계 4분기 손익은 연간에서 1~3분기를 차감해 산출했습니다.
A23: 한국 2사 분기 | B23: stockanalysis.com 분기 데이터 (KRX:000660 · KRX:005930), 2026년 8월 조회.
A24: 시가총액 (연간) | B24: companiesmarketcap.com, 달력 연말 기준 US$.
A26: ⚠ 이전 워크북에서 정정된 수치
A27: SK하이닉스 | B27: 기존 FCFF 워크북의 2016~2020년 수치 일부가 틀렸습니다. 감사보고서 기준으로 정정: 2017년 자산총계 40,289 → 45,418 · 2019년 71,299 → 65,248 · 2020년 85,284 → 71,174 (십억 원). 매출총이익도 여러 해가 달랐습니다.
A29: 정의 (Definitions) — 요청하신 정의를 그대로 사용했습니다
A30: Gross profit margin | B30: 영업이익 ÷ 매출액. 교과서에서는 보통 영업이익률(operating margin)이라 부릅니다. 교과서상 매출총이익률은 «참고» 행에 따로 있습니다.
A31: PE ratio | B31: 당기순이익 ÷ 시가총액. 통상적 P/E의 역수(이익수익률)입니다. 통상적 P/E는 «참고» 행에 있습니다.
A33: 주의 (Caveats)
A34: 마이크론 회계연도 | B34: 8~9월에 종료됩니다. 12월 결산인 한국 2사와 정확히 같은 기간이 아닙니다. 연말 시가총액은 3사 모두 달력 12월 말 기준이므로, 마이크론은 회계연도 종료 후 약 4개월 뒤 시점입니다.
A35: 환율 | B35: 연간은 평균환율(손익)·기말환율(재무상태표), 분기는 기말환율입니다. 모두 파란색 입력 칸이니 필요하면 바꾸십시오. 분기 환율 2021~2025년은 해당 연도 기말환율을 4개 분기에 공통 적용한 근사치입니다.
A36: 마이크론 4분기 | B36: 회계 4분기 손익은 연간에서 1~3분기를 뺀 값입니다(SEC에 별도 공시되지 않음). 해당 분기: 2021Q3, 2022Q3, 2023Q3, 2024Q3, 2025Q3.

Sheet 연간_10년
A1: 메모리 3사 핵심지표 — 연간 10년 (2016~2025)
A2: 전부 감사받은 재무제표 기준. 파란색 = 입력값, 초록색 = 수식, 노란색 = 환율 가정.
A4: 환율 가정 (FX assumptions) | B4: 2016 | C4: 2017 | D4: 2018 | E4: 2019 | F4: 2020 | G4: 2021 | H4: 2022 | I4: 2023 | J4: 2024 | K4: 2025
A5: 평균환율 · 손익계산서 환산용 (Average KRW/USD) | B5: 1160.4 | C5: 1130.4 | D5: 1100.6 | E5: 1165.7 | F5: 1180.3 | G5: 1144.46 | H5: 1291.41 | I5: 1306.01 | J5: 1363.53 | K5: 1422.16
A6: 기말환율 · 재무상태표 환산용 (Year-end KRW/USD) | B6: 1207.7 | C6: 1071.4 | D6: 1118.1 | E6: 1156.4 | F6: 1086.3 | G6: 1188.8 | H6: 1267.3 | I6: 1288 | J6: 1470 | K6: 1439
B8: SK하이닉스 (SK hynix) | M8: 삼성전자 (Samsung Electronics) | X8: 마이크론 (Micron Technology)
A9: 항목 (Metric) | B9: 2016 | C9: 2017 | D9: 2018 | E9: 2019 | F9: 2020 | G9: 2021 | H9: 2022 | I9: 2023 | J9: 2024 | K9: 2025 | M9: 2016 | N9: 2017 | O9: 2018 | P9: 2019 | Q9: 2020 | R9: 2021 | S9: 2022 | T9: 2023 | U9: 2024 | V9: 2025 | X9: FY16 | Y9: FY17 | Z9: FY18 | AA9: FY19 | AB9: FY20 | AC9: FY21 | AD9: FY22 | AE9: FY23 | AF9: FY24 | AG9: FY25
A10: 매출액 (Revenue, US$m) | B10: =IF(B27="","",B27*1000/B5) | C10: =IF(C27="","",C27*1000/C5) | D10: =IF(D27="","",D27*1000/D5) | E10: =IF(E27="","",E27*1000/E5) | F10: =IF(F27="","",F27*1000/F5) | G10: =IF(G27="","",G27*1000/G5) | H10: =IF(H27="","",H27*1000/H5) | I10: =IF(I27="","",I27*1000/I5) | ... K10: =IF(K27="","",K27*1000/K5) | M10: =IF(B36="","",B36*1000/B5) | N10: =IF(C36="","",C36*1000/C5) | O10: =IF(D36="","",D36*1000/D5) | P10: =IF(E36="","",E36*1000/E5) | Q10: =IF(F36="","",F36*1000/F5) | R10: =IF(G36="","",G36*1000/G5) | S10: =IF(H36="","",H36*1000/H5) | T10: =IF(I36="","",I36*1000/I5) | ... V10: =IF(K36="","",K36*1000/K5) | X10: =IF(B45="","",B45) | Y10: =IF(C45="","",C45) | Z10: =IF(D45="","",D45) | AA10: =IF(E45="","",E45) | AB10: =IF(F45="","",F45) | AC10: =IF(G45="","",G45) | AD10: =IF(H45="","",H45) | AE10: =IF(I45="","",I45) | ... AG10: =IF(K45="","",K45)
A11: 영업이익 (Operating income, US$m) | B11: =IF(B29="","",B29*1000/B5) | C11: =IF(C29="","",C29*1000/C5) | D11: =IF(D29="","",D29*1000/D5) | E11: =IF(E29="","",E29*1000/E5) | F11: =IF(F29="","",F29*1000/F5) | G11: =IF(G29="","",G29*1000/G5) | H11: =IF(H29="","",H29*1000/H5) | I11: =IF(I29="","",I29*1000/I5) | ... K11: =IF(K29="","",K29*1000/K5) | M11: =IF(B38="","",B38*1000/B5) | N11: =IF(C38="","",C38*1000/C5) | O11: =IF(D38="","",D38*1000/D5) | P11: =IF(E38="","",E38*1000/E5) | Q11: =IF(F38="","",F38*1000/F5) | R11: =IF(G38="","",G38*1000/G5) | S11: =IF(H38="","",H38*1000/H5) | T11: =IF(I38="","",I38*1000/I5) | ... V11: =IF(K38="","",K38*1000/K5) | X11: =IF(B47="","",B47) | Y11: =IF(C47="","",C47) | Z11: =IF(D47="","",D47) | AA11: =IF(E47="","",E47) | AB11: =IF(F47="","",F47) | AC11: =IF(G47="","",G47) | AD11: =IF(H47="","",H47) | AE11: =IF(I47="","",I47) | ... AG11: =IF(K47="","",K47)
A12: 당기순이익 (Net income, US$m) | B12: =IF(B30="","",B30*1000/B5) | C12: =IF(C30="","",C30*1000/C5) | D12: =IF(D30="","",D30*1000/D5) | E12: =IF(E30="","",E30*1000/E5) | F12: =IF(F30="","",F30*1000/F5) | G12: =IF(G30="","",G30*1000/G5) | H12: =IF(H30="","",H30*1000/H5) | I12: =IF(I30="","",I30*1000/I5) | ... K12: =IF(K30="","",K30*1000/K5) | M12: =IF(B39="","",B39*1000/B5) | N12: =IF(C39="","",C39*1000/C5) | O12: =IF(D39="","",D39*1000/D5) | P12: =IF(E39="","",E39*1000/E5) | Q12: =IF(F39="","",F39*1000/F5) | R12: =IF(G39="","",G39*1000/G5) | S12: =IF(H39="","",H39*1000/H5) | T12: =IF(I39="","",I39*1000/I5) | ... V12: =IF(K39="","",K39*1000/K5) | X12: =IF(B48="","",B48) | Y12: =IF(C48="","",C48) | Z12: =IF(D48="","",D48) | AA12: =IF(E48="","",E48) | AB12: =IF(F48="","",F48) | AC12: =IF(G48="","",G48) | AD12: =IF(H48="","",H48) | AE12: =IF(I48="","",I48) | ... AG12: =IF(K48="","",K48)
A13: 시가총액 · 연말 (Market cap, year-end, US$m) | B13: =IF(B33="","",B33) | C13: =IF(C33="","",C33) | D13: =IF(D33="","",D33) | E13: =IF(E33="","",E33) | F13: =IF(F33="","",F33) | G13: =IF(G33="","",G33) | H13: =IF(H33="","",H33) | I13: =IF(I33="","",I33) | ... K13: =IF(K33="","",K33) | M13: =IF(B42="","",B42) | N13: =IF(C42="","",C42) | O13: =IF(D42="","",D42) | P13: =IF(E42="","",E42) | Q13: =IF(F42="","",F42) | R13: =IF(G42="","",G42) | S13: =IF(H42="","",H42) | T13: =IF(I42="","",I42) | ... V13: =IF(K42="","",K42) | X13: =IF(B51="","",B51) | Y13: =IF(C51="","",C51) | Z13: =IF(D51="","",D51) | AA13: =IF(E51="","",E51) | AB13: =IF(F51="","",F51) | AC13: =IF(G51="","",G51) | AD13: =IF(H51="","",H51) | AE13: =IF(I51="","",I51) | ... AG13: =IF(K51="","",K51)
A14: 재고자산 (Inventories, US$m) | B14: =IF(B31="","",B31*1000/B6) | C14: =IF(C31="","",C31*1000/C6) | D14: =IF(D31="","",D31*1000/D6) | E14: =IF(E31="","",E31*1000/E6) | F14: =IF(F31="","",F31*1000/F6) | G14: =IF(G31="","",G31*1000/G6) | H14: =IF(H31="","",H31*1000/H6) | I14: =IF(I31="","",I31*1000/I6) | ... K14: =IF(K31="","",K31*1000/K6) | M14: =IF(B40="","",B40*1000/B6) | N14: =IF(C40="","",C40*1000/C6) | O14: =IF(D40="","",D40*1000/D6) | P14: =IF(E40="","",E40*1000/E6) | Q14: =IF(F40="","",F40*1000/F6) | R14: =IF(G40="","",G40*1000/G6) | S14: =IF(H40="","",H40*1000/H6) | T14: =IF(I40="","",I40*1000/I6) | ... V14: =IF(K40="","",K40*1000/K6) | X14: =IF(B49="","",B49) | Y14: =IF(C49="","",C49) | Z14: =IF(D49="","",D49) | AA14: =IF(E49="","",E49) | AB14: =IF(F49="","",F49) | AC14: =IF(G49="","",G49) | AD14: =IF(H49="","",H49) | AE14: =IF(I49="","",I49) | ... AG14: =IF(K49="","",K49)
A15: 자산총계 (Total assets, US$m) | B15: =IF(B32="","",B32*1000/B6) | C15: =IF(C32="","",C32*1000/C6) | D15: =IF(D32="","",D32*1000/D6) | E15: =IF(E32="","",E32*1000/E6) | F15: =IF(F32="","",F32*1000/F6) | G15: =IF(G32="","",G32*1000/G6) | H15: =IF(H32="","",H32*1000/H6) | I15: =IF(I32="","",I32*1000/I6) | ... K15: =IF(K32="","",K32*1000/K6) | M15: =IF(B41="","",B41*1000/B6) | N15: =IF(C41="","",C41*1000/C6) | O15: =IF(D41="","",D41*1000/D6) | P15: =IF(E41="","",E41*1000/E6) | Q15: =IF(F41="","",F41*1000/F6) | R15: =IF(G41="","",G41*1000/G6) | S15: =IF(H41="","",H41*1000/H6) | T15: =IF(I41="","",I41*1000/I6) | ... V15: =IF(K41="","",K41*1000/K6) | X15: =IF(B50="","",B50) | Y15: =IF(C50="","",C50) | Z15: =IF(D50="","",D50) | AA15: =IF(E50="","",E50) | AB15: =IF(F50="","",F50) | AC15: =IF(G50="","",G50) | AD15: =IF(H50="","",H50) | AE15: =IF(I50="","",I50) | ... AG15: =IF(K50="","",K50)
A17: Gross profit margin (영업이익 ÷ 매출액) | B17: =IFERROR(B11/B10,"") | C17: =IFERROR(C11/C10,"") | D17: =IFERROR(D11/D10,"") | E17: =IFERROR(E11/E10,"") | F17: =IFERROR(F11/F10,"") | G17: =IFERROR(G11/G10,"") | H17: =IFERROR(H11/H10,"") | I17: =IFERROR(I11/I10,"") | ... K17: =IFERROR(K11/K10,"") | M17: =IFERROR(M11/M10,"") | N17: =IFERROR(N11/N10,"") | O17: =IFERROR(O11/O10,"") | P17: =IFERROR(P11/P10,"") | Q17: =IFERROR(Q11/Q10,"") | R17: =IFERROR(R11/R10,"") | S17: =IFERROR(S11/S10,"") | T17: =IFERROR(T11/T10,"") | ... V17: =IFERROR(V11/V10,"") | X17: =IFERROR(X11/X10,"") | Y17: =IFERROR(Y11/Y10,"") | Z17: =IFERROR(Z11/Z10,"") | AA17: =IFERROR(AA11/AA10,"") | AB17: =IFERROR(AB11/AB10,"") | AC17: =IFERROR(AC11/AC10,"") | AD17: =IFERROR(AD11/AD10,"") | AE17: =IFERROR(AE11/AE10,"") | ... AG17: =IFERROR(AG11/AG10,"")
A18: Profit margin (당기순이익 ÷ 매출액) | B18: =IFERROR(B12/B10,"") | C18: =IFERROR(C12/C10,"") | D18: =IFERROR(D12/D10,"") | E18: =IFERROR(E12/E10,"") | F18: =IFERROR(F12/F10,"") | G18: =IFERROR(G12/G10,"") | H18: =IFERROR(H12/H10,"") | I18: =IFERROR(I12/I10,"") | ... K18: =IFERROR(K12/K10,"") | M18: =IFERROR(M12/M10,"") | N18: =IFERROR(N12/N10,"") | O18: =IFERROR(O12/O10,"") | P18: =IFERROR(P12/P10,"") | Q18: =IFERROR(Q12/Q10,"") | R18: =IFERROR(R12/R10,"") | S18: =IFERROR(S12/S10,"") | T18: =IFERROR(T12/T10,"") | ... V18: =IFERROR(V12/V10,"") | X18: =IFERROR(X12/X10,"") | Y18: =IFERROR(Y12/Y10,"") | Z18: =IFERROR(Z12/Z10,"") | AA18: =IFERROR(AA12/AA10,"") | AB18: =IFERROR(AB12/AB10,"") | AC18: =IFERROR(AC12/AC10,"") | AD18: =IFERROR(AD12/AD10,"") | AE18: =IFERROR(AE12/AE10,"") | ... AG18: =IFERROR(AG12/AG10,"")
A19: PE ratio (당기순이익 ÷ 시가총액) | B19: =IFERROR(B12/B13,"") | C19: =IFERROR(C12/C13,"") | D19: =IFERROR(D12/D13,"") | E19: =IFERROR(E12/E13,"") | F19: =IFERROR(F12/F13,"") | G19: =IFERROR(G12/G13,"") | H19: =IFERROR(H12/H13,"") | I19: =IFERROR(I12/I13,"") | ... K19: =IFERROR(K12/K13,"") | M19: =IFERROR(M12/M13,"") | N19: =IFERROR(N12/N13,"") | O19: =IFERROR(O12/O13,"") | P19: =IFERROR(P12/P13,"") | Q19: =IFERROR(Q12/Q13,"") | R19: =IFERROR(R12/R13,"") | S19: =IFERROR(S12/S13,"") | T19: =IFERROR(T12/T13,"") | ... V19: =IFERROR(V12/V13,"") | X19: =IFERROR(X12/X13,"") | Y19: =IFERROR(Y12/Y13,"") | Z19: =IFERROR(Z12/Z13,"") | AA19: =IFERROR(AA12/AA13,"") | AB19: =IFERROR(AB12/AB13,"") | AC19: =IFERROR(AC12/AC13,"") | AD19: =IFERROR(AD12/AD13,"") | AE19: =IFERROR(AE12/AE13,"") | ... AG19: =IFERROR(AG12/AG13,"")
A20: 재고자산 / 자산총계 (Inventory ÷ total assets) | B20: =IFERROR(B14/B15,"") | C20: =IFERROR(C14/C15,"") | D20: =IFERROR(D14/D15,"") | E20: =IFERROR(E14/E15,"") | F20: =IFERROR(F14/F15,"") | G20: =IFERROR(G14/G15,"") | H20: =IFERROR(H14/H15,"") | I20: =IFERROR(I14/I15,"") | ... K20: =IFERROR(K14/K15,"") | M20: =IFERROR(M14/M15,"") | N20: =IFERROR(N14/N15,"") | O20: =IFERROR(O14/O15,"") | P20: =IFERROR(P14/P15,"") | Q20: =IFERROR(Q14/Q15,"") | R20: =IFERROR(R14/R15,"") | S20: =IFERROR(S14/S15,"") | T20: =IFERROR(T14/T15,"") | ... V20: =IFERROR(V14/V15,"") | X20: =IFERROR(X14/X15,"") | Y20: =IFERROR(Y14/Y15,"") | Z20: =IFERROR(Z14/Z15,"") | AA20: =IFERROR(AA14/AA15,"") | AB20: =IFERROR(AB14/AB15,"") | AC20: =IFERROR(AC14/AC15,"") | AD20: =IFERROR(AD14/AD15,"") | AE20: =IFERROR(AE14/AE15,"") | ... AG20: =IFERROR(AG14/AG15,"")
A21: 참고: 매출총이익률 (매출총이익 ÷ 매출액) | B21: =IFERROR(B28/B27,"") | C21: =IFERROR(C28/C27,"") | D21: =IFERROR(D28/D27,"") | E21: =IFERROR(E28/E27,"") | F21: =IFERROR(F28/F27,"") | G21: =IFERROR(G28/G27,"") | H21: =IFERROR(H28/H27,"") | I21: =IFERROR(I28/I27,"") | ... K21: =IFERROR(K28/K27,"") | M21: =IFERROR(B37/B36,"") | N21: =IFERROR(C37/C36,"") | O21: =IFERROR(D37/D36,"") | P21: =IFERROR(E37/E36,"") | Q21: =IFERROR(F37/F36,"") | R21: =IFERROR(G37/G36,"") | S21: =IFERROR(H37/H36,"") | T21: =IFERROR(I37/I36,"") | ... V21: =IFERROR(K37/K36,"") | X21: =IFERROR(B46/B45,"") | Y21: =IFERROR(C46/C45,"") | Z21: =IFERROR(D46/D45,"") | AA21: =IFERROR(E46/E45,"") | AB21: =IFERROR(F46/F45,"") | AC21: =IFERROR(G46/G45,"") | AD21: =IFERROR(H46/H45,"") | AE21: =IFERROR(I46/I45,"") | ... AG21: =IFERROR(K46/K45,"")
A22: 참고: 통상적 P/E (시가총액 ÷ 당기순이익) | B22: =IF(OR(B12="",B13="",N(B12)<=0),"",B13/B12) | C22: =IF(OR(C12="",C13="",N(C12)<=0),"",C13/C12) | D22: =IF(OR(D12="",D13="",N(D12)<=0),"",D13/D12) | E22: =IF(OR(E12="",E13="",N(E12)<=0),"",E13/E12) | F22: =IF(OR(F12="",F13="",N(F12)<=0),"",F13/F12) | G22: =IF(OR(G12="",G13="",N(G12)<=0),"",G13/G12) | H22: =IF(OR(H12="",H13="",N(H12)<=0),"",H13/H12) | I22: =IF(OR(I12="",I13="",N(I12)<=0),"",I13/I12) | ... K22: =IF(OR(K12="",K13="",N(K12)<=0),"",K13/K12) | M22: =IF(OR(M12="",M13="",N(M12)<=0),"",M13/M12) | N22: =IF(OR(N12="",N13="",N(N12)<=0),"",N13/N12) | O22: =IF(OR(O12="",O13="",N(O12)<=0),"",O13/O12) | P22: =IF(OR(P12="",P13="",N(P12)<=0),"",P13/P12) | Q22: =IF(OR(Q12="",Q13="",N(Q12)<=0),"",Q13/Q12) | R22: =IF(OR(R12="",R13="",N(R12)<=0),"",R13/R12) | S22: =IF(OR(S12="",S13="",N(S12)<=0),"",S13/S12) | T22: =IF(OR(T12="",T13="",N(T12)<=0),"",T13/T12) | ... V22: =IF(OR(V12="",V13="",N(V12)<=0),"",V13/V12) | X22: =IF(OR(X12="",X13="",N(X12)<=0),"",X13/X12) | Y22: =IF(OR(Y12="",Y13="",N(Y12)<=0),"",Y13/Y12) | Z22: =IF(OR(Z12="",Z13="",N(Z12)<=0),"",Z13/Z12) | AA22: =IF(OR(AA12="",AA13="",N(AA12)<=0),"",AA13/AA12) | AB22: =IF(OR(AB12="",AB13="",N(AB12)<=0),"",AB13/AB12) | AC22: =IF(OR(AC12="",AC13="",N(AC12)<=0),"",AC13/AC12) | AD22: =IF(OR(AD12="",AD13="",N(AD12)<=0),"",AD13/AD12) | AE22: =IF(OR(AE12="",AE13="",N(AE12)<=0),"",AE13/AE12) | ... AG22: =IF(OR(AG12="",AG13="",N(AG12)<=0),"",AG13/AG12)
A24: 원자료 — 보고통화 기준 (Source data in reporting currency)
A25: SK하이닉스·삼성전자: 십억 원 (KRW bn) · 마이크론: 백만 달러 (US$m) · 시가총액은 3사 모두 백만 달러 (US$m).
A26: SK하이닉스 (SK hynix) — 십억 원 (KRW bn) | B26: 2016 | C26: 2017 | D26: 2018 | E26: 2019 | F26: 2020 | G26: 2021 | H26: 2022 | I26: 2023 | J26: 2024 | K26: 2025
A27: 매출액 (Revenue) | B27: 17198 | C27: 30109 | D27: 40445 | E27: 26991 | F27: 31900 | G27: 42998 | H27: 44648 | I27: 32766 | J27: 66193 | K27: 97147
A28: 매출총이익 (Gross profit) | B28: 6411 | C28: 17408 | D28: 25264 | E28: 8172 | F28: 10811 | G28: 20265 | H28: 16193 | I28: -533 | J28: 31828 | K28: 58691
A29: 영업이익 (Operating income) | B29: 3277 | C29: 13721 | D29: 20844 | E29: 2719 | F29: 5013 | G29: 12410 | H29: 7007 | I29: -7730 | J29: 23468 | K29: 47206
A30: 당기순이익 (Net income) | B30: 2960 | C30: 10642 | D30: 15540 | E30: 2009 | F30: 4759 | G30: 9617 | H30: 2439 | I30: -9138 | J30: 19797 | K30: 42948
A31: 재고자산 (Inventories) | B31: 2026 | C31: 2640 | D31: 4423 | E31: 5296 | F31: 6136 | G31: 8950 | H31: 15665 | I31: 13481 | J31: 13314 | K31: 14289
A32: 자산총계 (Total assets) | B32: 32216 | C32: 45418 | D32: 63658 | E32: 65248 | F32: 71174 | G32: 96347 | H32: 103872 | I32: 100330 | J32: 119855 | K32: 176108
A33: 시가총액 · 연말 (Market cap, year-end) [US$m] | B33: 26180 | C33: 50490 | D33: 37070 | E33: 55660 | F33: 74600 | G33: 75700 | H33: 40650 | I33: 77400 | J33: 81730 | K33: 286610
A35: 삼성전자 (Samsung Electronics) — 십억 원 (KRW bn) | B35: 2016 | C35: 2017 | D35: 2018 | E35: 2019 | F35: 2020 | G35: 2021 | H35: 2022 | I35: 2023 | J35: 2024 | K35: 2025
A36: 매출액 (Revenue) | B36: 201867 | C36: 239575 | D36: 243771 | E36: 230401 | F36: 236807 | G36: 279605 | H36: 302231 | I36: 258935 | J36: 300871 | K36: 333606
A37: 매출총이익 (Gross profit) | B37: 81589 | C37: 110285 | D37: 111377 | E37: 83161 | F37: 92319 | G37: 113193 | H37: 112190 | I37: 78547 | J37: 114309 | K37: 131370
A38: 영업이익 (Operating income) | B38: 29241 | C38: 53645 | D38: 58887 | E38: 27769 | F38: 35994 | G38: 51634 | H38: 43377 | I38: 6567 | J38: 32726 | K38: 43601
A39: 당기순이익 (Net income) | B39: 22726 | C39: 42187 | D39: 44345 | E39: 21739 | F39: 26408 | G39: 39244 | H39: 54730 | I39: 14473 | J39: 33621 | K39: 44261
A40: 재고자산 (Inventories) | B40: 18354 | C40: 24983 | D40: 28985 | E40: 26766 | F40: 32043 | G40: 41384 | H40: 52188 | I40: 51626 | J40: 51755 | K40: 52637
A41: 자산총계 (Total assets) | B41: 262174 | C41: 301752 | D41: 339357 | E41: 352564 | F41: 378236 | G41: 426621 | H41: 448425 | I41: 455906 | J41: 514532 | K41: 566942
A42: 시가총액 · 연말 (Market cap, year-end) [US$m] | B42: 203990 | C42: 319260 | D42: 230360 | E42: 319730 | F42: 500830 | G42: 442070 | H42: 293000 | I42: 401540 | J42: 242970 | K42: 542110
A44: 마이크론 (Micron Technology) — 백만 달러 (US$m) | B44: FY16 | C44: FY17 | D44: FY18 | E44: FY19 | F44: FY20 | G44: FY21 | H44: FY22 | I44: FY23 | J44: FY24 | K44: FY25
A45: 매출액 (Revenue) | B45: 12399 | C45: 20322 | D45: 30391 | E45: 23406 | F45: 21435 | G45: 27705 | H45: 30758 | I45: 15540 | J45: 25111 | K45: 37378
A46: 매출총이익 (Gross profit) | B46: 2505 | C46: 8436 | D46: 17891 | E46: 10702 | F46: 6552 | G46: 10423 | H46: 13898 | I46: -1416 | J46: 5613 | K46: 14873
...

Sheet SK하이닉스_분기
A1: SK하이닉스 (SK hynix) — 분기 데이터 (Quarterly, 2016Q3~2026Q2)
A2: 단위: 십억 원 (KRW bn) · 2021Q3 이후 20개 분기만 채워져 있습니다 · 파란색 칸은 입력값입니다.
A4: 항목 (Metric) | B4: 2021Q3 | C4: 2021Q4 | D4: 2022Q1 | E4: 2022Q2 | F4: 2022Q3 | G4: 2022Q4 | H4: 2023Q1 | I4: 2023Q2 | J4: 2023Q3 | K4: 2023Q4 | L4: 2024Q1 | M4: 2024Q2 | N4: 2024Q3 | O4: 2024Q4 | P4: 2025Q1 | Q4: 2025Q2 | R4: 2025Q3 | S4: 2025Q4 | T4: 2026Q1 | U4: 2026Q2
A5: 손익계산서 및 시장가치 (Income statement & market value)
A6: 매출액 (Revenue) | B6: 11805 | C6: 12377 | D6: 12156 | E6: 13811 | F6: 10983 | G6: 7672 | H6: 5088 | I6: 7306 | J6: 9066 | K6: 11306 | L6: 12430 | M6: 16423 | N6: 17573 | O6: 19767 | P6: 17639 | Q6: 22232 | R6: 24449 | S6: 32827 | T6: 52576 | U6: 79319
A7: 매출총이익 (Gross profit) | B7: 5831 | C7: 6053 | D7: 5401 | E7: 6338 | F7: 3866 | G7: 23 | H7: -1645 | I7: -1178 | J7: 64 | K7: 2226 | L7: 4795 | M7: 7496 | N7: 9171 | O7: 10366 | P7: 10102 | Q7: 11983 | R7: 14029 | S7: 22576 | T7: 41679 | U7: 65992
A8: 영업이익 (Operating income) | B8: 4172 | C8: 4220 | D8: 2864 | E8: 4197 | F8: 1661 | G8: -1912 | H8: -3402 | I8: -2882 | J8: -1792 | K8: 346 | L8: 2886 | M8: 5469 | N8: 7030 | O8: 8083 | P8: 7441 | Q8: 9213 | R8: 11383 | S8: 19170 | T8: 37610 | U8: 60543
A9: 당기순이익 (Net income) | B9: 3311 | C9: 3317 | D9: 1983 | E9: 2876 | F9: 1112 | G9: -3741 | H9: -2580 | I9: -2991 | J9: -2184 | K9: -1357 | L9: 1919 | M9: 4120 | N9: 5749 | O9: 8000 | P9: 8107 | Q9: 6997 | R9: 12595 | S9: 15220 | T9: 40330 | U9: 93923
A10: 시가총액 · 분기말 (Market cap, quarter-end) | B10: 70825 | C10: 90078 | D10: 81139 | E10: 62576 | F10: 57144 | G10: 51574 | H10: 60926 | I10: 79264 | J10: 78924 | K10: 97368 | L10: 125929 | M10: 162745 | N10: 120233 | O10: 119824 | P10: 131400 | Q10: 201581 | R10: 239918 | S10: 449486 | T10: 566265 | U10: 1876987
A11: PE ratio (당기순이익 ÷ 시가총액) | B11: =IF(OR(B9="",B10=""),"",B9/B10) | C11: =IF(OR(C9="",C10=""),"",C9/C10) | D11: =IF(OR(D9="",D10=""),"",D9/D10) | E11: =IF(OR(E9="",E10=""),"",E9/E10) | F11: =IF(OR(F9="",F10=""),"",F9/F10) | G11: =IF(OR(G9="",G10=""),"",G9/G10) | H11: =IF(OR(H9="",H10=""),"",H9/H10) | I11: =IF(OR(I9="",I10=""),"",I9/I10) | ... U11: =IF(OR(U9="",U10=""),"",U9/U10)
A12: 참고: 통상적 P/E (시가총액 ÷ 당기순이익) | B12: =IF(OR(B9="",B10="",N(B9)<=0),"",B10/B9) | C12: =IF(OR(C9="",C10="",N(C9)<=0),"",C10/C9) | D12: =IF(OR(D9="",D10="",N(D9)<=0),"",D10/D9) | E12: =IF(OR(E9="",E10="",N(E9)<=0),"",E10/E9) | F12: =IF(OR(F9="",F10="",N(F9)<=0),"",F10/F9) | G12: =IF(OR(G9="",G10="",N(G9)<=0),"",G10/G9) | H12: =IF(OR(H9="",H10="",N(H9)<=0),"",H10/H9) | I12: =IF(OR(I9="",I10="",N(I9)<=0),"",I10/I9) | ... U12: =IF(OR(U9="",U10="",N(U9)<=0),"",U10/U9)
A14: 재무상태표 (Balance sheet, 기말)
A15: 재고자산 (Inventories) | B15: 6600 | C15: 8950 | D15: 10393 | E15: 11879 | F15: 14665 | G15: 15665 | H15: 17182 | I15: 16420 | J15: 14948 | K15: 13481 | L15: 13845 | M15: 13355 | N15: 13354 | O15: 13314 | P15: 14551 | Q15: 13408 | R15: 13156 | S15: 14289 | T15: 15974 | U15: 17986
A16: 자산총계 (Total assets) | B16: 83269 | C16: 96347 | D16: 99466 | E16: 104148 | F16: 109546 | G16: 103872 | H16: 104385 | I16: 102819 | J16: 102049 | K16: 100330 | L16: 103198 | M16: 105624 | N16: 108367 | O16: 119855 | P16: 123985 | Q16: 129088 | R16: 148435 | S16: 176108 | T16: 222829 | U16: 348862
A18: 비율 (Ratios)
A19: Gross profit margin (영업이익 ÷ 매출액) | B19: =IF(OR(B8="",B6=""),"",B8/B6) | C19: =IF(OR(C8="",C6=""),"",C8/C6) | D19: =IF(OR(D8="",D6=""),"",D8/D6) | E19: =IF(OR(E8="",E6=""),"",E8/E6) | F19: =IF(OR(F8="",F6=""),"",F8/F6) | G19: =IF(OR(G8="",G6=""),"",G8/G6) | H19: =IF(OR(H8="",H6=""),"",H8/H6) | I19: =IF(OR(I8="",I6=""),"",I8/I6) | ... U19: =IF(OR(U8="",U6=""),"",U8/U6)
A20: Profit margin (당기순이익 ÷ 매출액) | B20: =IF(OR(B9="",B6=""),"",B9/B6) | C20: =IF(OR(C9="",C6=""),"",C9/C6) | D20: =IF(OR(D9="",D6=""),"",D9/D6) | E20: =IF(OR(E9="",E6=""),"",E9/E6) | F20: =IF(OR(F9="",F6=""),"",F9/F6) | G20: =IF(OR(G9="",G6=""),"",G9/G6) | H20: =IF(OR(H9="",H6=""),"",H9/H6) | I20: =IF(OR(I9="",I6=""),"",I9/I6) | ... U20: =IF(OR(U9="",U6=""),"",U9/U6)
A21: 재고자산 / 자산총계 (Inventory ÷ total assets) | B21: =IF(OR(B15="",B16=""),"",B15/B16) | C21: =IF(OR(C15="",C16=""),"",C15/C16) | D21: =IF(OR(D15="",D16=""),"",D15/D16) | E21: =IF(OR(E15="",E16=""),"",E15/E16) | F21: =IF(OR(F15="",F16=""),"",F15/F16) | G21: =IF(OR(G15="",G16=""),"",G15/G16) | H21: =IF(OR(H15="",H16=""),"",H15/H16) | I21: =IF(OR(I15="",I16=""),"",I15/I16) | ... U21: =IF(OR(U15="",U16=""),"",U15/U16)
A22: 참고: 매출총이익률 (매출총이익 ÷ 매출액) | B22: =IF(OR(B7="",B6=""),"",B7/B6) | C22: =IF(OR(C7="",C6=""),"",C7/C6) | D22: =IF(OR(D7="",D6=""),"",D7/D6) | E22: =IF(OR(E7="",E6=""),"",E7/E6) | F22: =IF(OR(F7="",F6=""),"",F7/F6) | G22: =IF(OR(G7="",G6=""),"",G7/G6) | H22: =IF(OR(H7="",H6=""),"",H7/H6) | I22: =IF(OR(I7="",I6=""),"",I7/I6) | ... U22: =IF(OR(U7="",U6=""),"",U7/U6)
A24: US$ 환산 (Converted to US$ millions)
A25: 적용환율 · 분기말 KRW/USD (FX rate applied) | B25: 1188.8 | C25: 1188.8 | D25: 1267.3 | E25: 1267.3 | F25: 1267.3 | G25: 1267.3 | H25: 1288 | I25: 1288 | J25: 1288 | K25: 1288 | L25: 1470 | M25: 1470 | N25: 1470 | O25: 1470 | P25: 1439 | Q25: 1439 | R25: 1439 | S25: 1439 | T25: 1537.15 | U25: 1545
A26: 재고자산 (Inventories, US$m) | B26: =IF(OR(B15="",B25=""),"",B15*1000/B25) | C26: =IF(OR(C15="",C25=""),"",C15*1000/C25) | D26: =IF(OR(D15="",D25=""),"",D15*1000/D25) | E26: =IF(OR(E15="",E25=""),"",E15*1000/E25) | F26: =IF(OR(F15="",F25=""),"",F15*1000/F25) | G26: =IF(OR(G15="",G25=""),"",G15*1000/G25) | H26: =IF(OR(H15="",H25=""),"",H15*1000/H25) | I26: =IF(OR(I15="",I25=""),"",I15*1000/I25) | ... U26: =IF(OR(U15="",U25=""),"",U15*1000/U25)
A27: 영업이익 (Operating income, US$m) | B27: =IF(OR(B8="",B25=""),"",B8*1000/B25) | C27: =IF(OR(C8="",C25=""),"",C8*1000/C25) | D27: =IF(OR(D8="",D25=""),"",D8*1000/D25) | E27: =IF(OR(E8="",E25=""),"",E8*1000/E25) | F27: =IF(OR(F8="",F25=""),"",F8*1000/F25) | G27: =IF(OR(G8="",G25=""),"",G8*1000/G25) | H27: =IF(OR(H8="",H25=""),"",H8*1000/H25) | I27: =IF(OR(I8="",I25=""),"",I8*1000/I25) | ... U27: =IF(OR(U8="",U25=""),"",U8*1000/U25)
A28: 시가총액 (Market cap, US$m) | B28: =IF(OR(B10="",B25=""),"",B10*1000/B25) | C28: =IF(OR(C10="",C25=""),"",C10*1000/C25) | D28: =IF(OR(D10="",D25=""),"",D10*1000/D25) | E28: =IF(OR(E10="",E25=""),"",E10*1000/E25) | F28: =IF(OR(F10="",F25=""),"",F10*1000/F25) | G28: =IF(OR(G10="",G25=""),"",G10*1000/G25) | H28: =IF(OR(H10="",H25=""),"",H10*1000/H25) | I28: =IF(OR(I10="",I25=""),"",I10*1000/I25) | ... U28: =IF(OR(U10="",U25=""),"",U10*1000/U25)

Sheet 삼성전자_분기
A1: 삼성전자 (Samsung Electronics) — 분기 데이터 (Quarterly, 2016Q3~2026Q2)
A2: 단위: 십억 원 (KRW bn) · 2021Q3 이후 20개 분기만 채워져 있습니다 · 파란색 칸은 입력값입니다.
A4: 항목 (Metric) | B4: 2021Q3 | C4: 2021Q4 | D4: 2022Q1 | E4: 2022Q2 | F4: 2022Q3 | G4: 2022Q4 | H4: 2023Q1 | I4: 2023Q2 | J4: 2023Q3 | K4: 2023Q4 | L4: 2024Q1 | M4: 2024Q2 | N4: 2024Q3 | O4: 2024Q4 | P4: 2025Q1 | Q4: 2025Q2 | R4: 2025Q3 | S4: 2025Q4 | T4: 2026Q1 | U4: 2026Q2
A5: 손익계산서 및 시장가치 (Income statement & market value)
A6: 매출액 (Revenue) | B6: 73979 | C6: 76565 | D6: 77781 | E6: 77204 | F6: 76782 | G6: 70470 | H6: 63745 | I6: 60006 | J6: 67405 | K6: 67775 | L6: 71916 | M6: 74068 | N6: 79099 | O6: 75785 | P6: 79141 | Q6: 74566 | R6: 86062 | S6: 93806 | T6: 133873 | U6: 171500
A7: 매출총이익 (Gross profit) | B7: 31080 | C7: 31623 | D7: 30709 | E7: 30934 | F7: 28709 | G7: 21840 | H7: 17738 | I7: 18358 | J7: 20786 | K7: 21667 | L7: 26029 | M7: 29756 | N7: 30004 | O7: 28519 | P7: 28131 | Q7: 25497 | R7: 33492 | S7: 44270 | T7: 81913 | U7: 119300
A8: 영업이익 (Operating income) | B8: 15818 | C8: 13874 | D8: 14121 | E8: 14097 | F8: 10852 | G8: 4315 | H8: 640 | I8: 669 | J8: 2434 | K8: 2827 | L8: 6606 | M8: 10444 | N8: 9183 | O8: 6490 | P8: 6685 | Q8: 4676 | R8: 12166 | S8: 20001 | T8: 57233 | U8: 89500
A9: 당기순이익 (Net income) | B9: 12057 | C9: 10644 | D9: 11129 | E9: 10955 | F9: 9144 | G9: 23511 | H9: 1401 | I9: 1547 | J9: 5501 | K9: 6023 | L9: 6621 | M9: 9643 | N9: 9782 | O9: 7580 | P9: 8028 | Q9: 4337 | R9: 10553 | S9: 19361 | T9: 47101 | U9: 71300
A10: 시가총액 · 분기말 (Market cap, quarter-end) | B10: 499634 | C10: 526024 | D10: 467339 | E10: 383068 | F10: 355589 | G10: 371685 | H10: 426420 | I10: 479980 | J10: 453180 | K10: 519894 | L10: 547866 | M10: 538873 | N10: 409027 | O10: 353964 | P10: 377444 | Q10: 391492 | R10: 546799 | S10: 769602 | T10: 1061034 | U10: 2104819
A11: PE ratio (당기순이익 ÷ 시가총액) | B11: =IF(OR(B9="",B10=""),"",B9/B10) | C11: =IF(OR(C9="",C10=""),"",C9/C10) | D11: =IF(OR(D9="",D10=""),"",D9/D10) | E11: =IF(OR(E9="",E10=""),"",E9/E10) | F11: =IF(OR(F9="",F10=""),"",F9/F10) | G11: =IF(OR(G9="",G10=""),"",G9/G10) | H11: =IF(OR(H9="",H10=""),"",H9/H10) | I11: =IF(OR(I9="",I10=""),"",I9/I10) | ... U11: =IF(OR(U9="",U10=""),"",U9/U10)
A12: 참고: 통상적 P/E (시가총액 ÷ 당기순이익) | B12: =IF(OR(B9="",B10="",N(B9)<=0),"",B10/B9) | C12: =IF(OR(C9="",C10="",N(C9)<=0),"",C10/C9) | D12: =IF(OR(D9="",D10="",N(D9)<=0),"",D10/D9) | E12: =IF(OR(E9="",E10="",N(E9)<=0),"",E10/E9) | F12: =IF(OR(F9="",F10="",N(F9)<=0),"",F10/F9) | G12: =IF(OR(G9="",G10="",N(G9)<=0),"",G10/G9) | H12: =IF(OR(H9="",H10="",N(H9)<=0),"",H10/H9) | I12: =IF(OR(I9="",I10="",N(I9)<=0),"",I10/I9) | ... U12: =IF(OR(U9="",U10="",N(U9)<=0),"",U10/U9)
A14: 재무상태표 (Balance sheet, 기말)
A15: 재고자산 (Inventories) | B15: 37802 | C15: 41384 | D15: 47591 | E15: 52092 | F15: 57320 | G15: 52188 | H15: 54420 | I15: 55505 | J15: 55256 | K15: 51626 | L15: 53348 | M15: 55567 | N15: 53357 | O15: 51755 | P15: 53220 | Q15: 51037 | R15: 50332 | S15: 52637 | T15: 58278 | U15: 71389
A16: 자산총계 (Total assets) | B16: 410421 | C16: 426621 | D16: 439327 | E16: 448041 | F16: 470278 | G16: 448425 | H16: 454092 | I16: 448001 | J16: 454466 | K16: 455906 | L16: 470900 | M16: 485758 | N16: 491307 | O16: 514532 | P16: 516377 | Q16: 504875 | R16: 523660 | S16: 566942 | T16: 633340 | U16: 759481
A18: 비율 (Ratios)
A19: Gross profit margin (영업이익 ÷ 매출액) | B19: =IF(OR(B8="",B6=""),"",B8/B6) | C19: =IF(OR(C8="",C6=""),"",C8/C6) | D19: =IF(OR(D8="",D6=""),"",D8/D6) | E19: =IF(OR(E8="",E6=""),"",E8/E6) | F19: =IF(OR(F8="",F6=""),"",F8/F6) | G19: =IF(OR(G8="",G6=""),"",G8/G6) | H19: =IF(OR(H8="",H6=""),"",H8/H6) | I19: =IF(OR(I8="",I6=""),"",I8/I6) | ... U19: =IF(OR(U8="",U6=""),"",U8/U6)
A20: Profit margin (당기순이익 ÷ 매출액) | B20: =IF(OR(B9="",B6=""),"",B9/B6) | C20: =IF(OR(C9="",C6=""),"",C9/C6) | D20: =IF(OR(D9="",D6=""),"",D9/D6) | E20: =IF(OR(E9="",E6=""),"",E9/E6) | F20: =IF(OR(F9="",F6=""),"",F9/F6) | G20: =IF(OR(G9="",G6=""),"",G9/G6) | H20: =IF(OR(H9="",H6=""),"",H9/H6) | I20: =IF(OR(I9="",I6=""),"",I9/I6) | ... U20: =IF(OR(U9="",U6=""),"",U9/U6)
A21: 재고자산 / 자산총계 (Inventory ÷ total assets) | B21: =IF(OR(B15="",B16=""),"",B15/B16) | C21: =IF(OR(C15="",C16=""),"",C15/C16) | D21: =IF(OR(D15="",D16=""),"",D15/D16) | E21: =IF(OR(E15="",E16=""),"",E15/E16) | F21: =IF(OR(F15="",F16=""),"",F15/F16) | G21: =IF(OR(G15="",G16=""),"",G15/G16) | H21: =IF(OR(H15="",H16=""),"",H15/H16) | I21: =IF(OR(I15="",I16=""),"",I15/I16) | ... U21: =IF(OR(U15="",U16=""),"",U15/U16)
A22: 참고: 매출총이익률 (매출총이익 ÷ 매출액) | B22: =IF(OR(B7="",B6=""),"",B7/B6) | C22: =IF(OR(C7="",C6=""),"",C7/C6) | D22: =IF(OR(D7="",D6=""),"",D7/D6) | E22: =IF(OR(E7="",E6=""),"",E7/E6) | F22: =IF(OR(F7="",F6=""),"",F7/F6) | G22: =IF(OR(G7="",G6=""),"",G7/G6) | H22: =IF(OR(H7="",H6=""),"",H7/H6) | I22: =IF(OR(I7="",I6=""),"",I7/I6) | ... U22: =IF(OR(U7="",U6=""),"",U7/U6)
A24: US$ 환산 (Converted to US$ millions)
A25: 적용환율 · 분기말 KRW/USD (FX rate applied) | B25: 1188.8 | C25: 1188.8 | D25: 1267.3 | E25: 1267.3 | F25: 1267.3 | G25: 1267.3 | H25: 1288 | I25: 1288 | J25: 1288 | K25: 1288 | L25: 1470 | M25: 1470 | N25: 1470 | O25: 1470 | P25: 1439 | Q25: 1439 | R25: 1439 | S25: 1439 | T25: 1537.15 | U25: 1545
A26: 재고자산 (Inventories, US$m) | B26: =IF(OR(B15="",B25=""),"",B15*1000/B25) | C26: =IF(OR(C15="",C25=""),"",C15*1000/C25) | D26: =IF(OR(D15="",D25=""),"",D15*1000/D25) | E26: =IF(OR(E15="",E25=""),"",E15*1000/E25) | F26: =IF(OR(F15="",F25=""),"",F15*1000/F25) | G26: =IF(OR(G15="",G25=""),"",G15*1000/G25) | H26: =IF(OR(H15="",H25=""),"",H15*1000/H25) | I26: =IF(OR(I15="",I25=""),"",I15*1000/I25) | ... U26: =IF(OR(U15="",U25=""),"",U15*1000/U25)
A27: 영업이익 (Operating income, US$m) | B27: =IF(OR(B8="",B25=""),"",B8*1000/B25) | C27: =IF(OR(C8="",C25=""),"",C8*1000/C25) | D27: =IF(OR(D8="",D25=""),"",D8*1000/D25) | E27: =IF(OR(E8="",E25=""),"",E8*1000/E25) | F27: =IF(OR(F8="",F25=""),"",F8*1000/F25) | G27: =IF(OR(G8="",G25=""),"",G8*1000/G25) | H27: =IF(OR(H8="",H25=""),"",H8*1000/H25) | I27: =IF(OR(I8="",I25=""),"",I8*1000/I25) | ... U27: =IF(OR(U8="",U25=""),"",U8*1000/U25)
A28: 시가총액 (Market cap, US$m) | B28: =IF(OR(B10="",B25=""),"",B10*1000/B25) | C28: =IF(OR(C10="",C25=""),"",C10*1000/C25) | D28: =IF(OR(D10="",D25=""),"",D10*1000/D25) | E28: =IF(OR(E10="",E25=""),"",E10*1000/E25) | F28: =IF(OR(F10="",F25=""),"",F10*1000/F25) | G28: =IF(OR(G10="",G25=""),"",G10*1000/G25) | H28: =IF(OR(H10="",H25=""),"",H10*1000/H25) | I28: =IF(OR(I10="",I25=""),"",I10*1000/I25) | ... U28: =IF(OR(U10="",U25=""),"",U10*1000/U25)

Sheet 마이크론_분기
A1: 마이크론 (Micron Technology) — 분기 데이터 (Quarterly, 2016Q3~2026Q2)
A2: 단위: 백만 달러 (US$m) · 40개 분기 전체 (SEC XBRL) · 파란색 칸은 입력값입니다. 마이크론 회계분기를 달력분기에 정렬했습니다.
A4: 항목 (Metric) | B4: 2016Q3 | C4: 2016Q4 | D4: 2017Q1 | E4: 2017Q2 | F4: 2017Q3 | G4: 2017Q4 | H4: 2018Q1 | I4: 2018Q2 | J4: 2018Q3 | K4: 2018Q4 | L4: 2019Q1 | M4: 2019Q2 | N4: 2019Q3 | O4: 2019Q4 | P4: 2020Q1 | Q4: 2020Q2 | R4: 2020Q3 | S4: 2020Q4 | T4: 2021Q1 | U4: 2021Q2 | V4: 2021Q3 | W4: 2021Q4 | X4: 2022Q1 | Y4: 2022Q2 | Z4: 2022Q3 | AA4: 2022Q4 | AB4: 2023Q1 | AC4: 2023Q2 | AD4: 2023Q3 | AE4: 2023Q4 | AF4: 2024Q1 | AG4: 2024Q2 | AH4: 2024Q3 | AI4: 2024Q4 | AJ4: 2025Q1 | AK4: 2025Q2 | AL4: 2025Q3 | AM4: 2025Q4 | AN4: 2026Q1 | AO4: 2026Q2
A5: 손익계산서 및 시장가치 (Income statement & market value)
A6: 매출액 (Revenue) | B6: 3217 | C6: 3970 | D6: 4648 | E6: 5566 | F6: 6138 | G6: 6803 | H6: 7351 | I6: 7797 | J6: 8440 | K6: 7913 | L6: 5835 | M6: 4788 | N6: 4870 | O6: 5144 | P6: 4797 | Q6: 5438 | R6: 6056 | S6: 5773 | T6: 6236 | U6: 7422 | V6: 8274 | W6: 7687 | X6: 7786 | Y6: 8642 | Z6: 6643 | AA6: 4085 | AB6: 3693 | AC6: 3752 | AD6: 4010 | AE6: 4726 | AF6: 5824 | AG6: 6811 | AH6: 7750 | AI6: 8709 | AJ6: 8053 | AK6: 9301 | AL6: 11315 | AM6: 13643 | AN6: 23860 | AO6: 41456
A7: 매출총이익 (Gross profit) | B7: 579 | C7: 1011 | D7: 1704 | E7: 2609 | F7: 3112 | G7: 3747 | H7: 4270 | I7: 4723 | J7: 5151 | K7: 4615 | L7: 2864 | M7: 1828 | N7: 1395 | O7: 1366 | P7: 1355 | Q7: 1763 | R7: 2068 | S7: 1736 | T7: 1649 | U7: 3126 | V7: 3912 | W7: 3565 | X7: 3676 | Y7: 4035 | Z7: 2622 | AA7: 893 | AB7: -1206 | AC7: -668 | AD7: -435 | AE7: -35 | AF7: 1079 | AG7: 1832 | AH7: 2737 | AI7: 3348 | AJ7: 2963 | AK7: 3508 | AL7: 5054 | AM7: 7646 | AN7: 17755 | AO7: 35056
A8: 영업이익 (Operating income) | B8: -32 | C8: 359 | D8: 1044 | E8: 1963 | F8: 2502 | G8: 3097 | H8: 3567 | I8: 3953 | J8: 4377 | K8: 3759 | L8: 1957 | M8: 1010 | N8: 650 | O8: 518 | P8: 440 | Q8: 888 | R8: 1157 | S8: 866 | T8: 663 | U8: 1799 | V8: 2955 | W8: 2631 | X8: 2546 | Y8: 3004 | Z8: 1521 | AA8: -209 | AB8: -2303 | AC8: -1761 | AD8: -1472 | AE8: -1128 | AF8: 191 | AG8: 719 | AH8: 1522 | AI8: 2174 | AJ8: 1773 | AK8: 2169 | AL8: 3654 | AM8: 6136 | AN8: 16135 | AO8: 33318
A9: 당기순이익 (Net income) | B9: -170 | C9: 180 | D9: 894 | E9: 1647 | F9: 2368 | G9: 2678 | H9: 3309 | I9: 3823 | J9: 4325 | K9: 3293 | L9: 1619 | M9: 840 | N9: 561 | O9: 491 | P9: 405 | Q9: 803 | R9: 988 | S9: 803 | T9: 603 | U9: 1735 | V9: 2720 | W9: 2306 | X9: 2263 | Y9: 2626 | Z9: 1492 | AA9: -195 | AB9: -2312 | AC9: -1896 | AD9: -1430 | AE9: -1234 | AF9: 793 | AG9: 332 | AH9: 887 | AI9: 1870 | AJ9: 1583 | AK9: 1885 | AL9: 3201 | AM9: 5240 | AN9: 13785 | AO9: 28243
A10: 시가총액 · 분기말 (Market cap, quarter-end) | W10: 92826 | X10: 99703 | Y10: 83284 | Z10: 62697 | AA10: 60540 | AB10: 61734 | AC10: 75654 | AD10: 76794 | AE10: 84036 | AF10: 100305 | AG10: 140056 | AH10: 105987 | AI10: 109395 | AJ10: 102655 | AK10: 108319 | AL10: 136884 | AM10: 259273 | AN10: 468752 | AO10: 1042654
A11: PE ratio (당기순이익 ÷ 시가총액) | B11: =IF(OR(B9="",B10=""),"",B9/B10) | C11: =IF(OR(C9="",C10=""),"",C9/C10) | D11: =IF(OR(D9="",D10=""),"",D9/D10) | E11: =IF(OR(E9="",E10=""),"",E9/E10) | F11: =IF(OR(F9="",F10=""),"",F9/F10) | G11: =IF(OR(G9="",G10=""),"",G9/G10) | H11: =IF(OR(H9="",H10=""),"",H9/H10) | I11: =IF(OR(I9="",I10=""),"",I9/I10) | ... AO11: =IF(OR(AO9="",AO10=""),"",AO9/AO10)
A12: 참고: 통상적 P/E (시가총액 ÷ 당기순이익) | B12: =IF(OR(B9="",B10="",N(B9)<=0),"",B10/B9) | C12: =IF(OR(C9="",C10="",N(C9)<=0),"",C10/C9) | D12: =IF(OR(D9="",D10="",N(D9)<=0),"",D10/D9) | E12: =IF(OR(E9="",E10="",N(E9)<=0),"",E10/E9) | F12: =IF(OR(F9="",F10="",N(F9)<=0),"",F10/F9) | G12: =IF(OR(G9="",G10="",N(G9)<=0),"",G10/G9) | H12: =IF(OR(H9="",H10="",N(H9)<=0),"",H10/H9) | I12: =IF(OR(I9="",I10="",N(I9)<=0),"",I10/I9) | ... AO12: =IF(OR(AO9="",AO10="",N(AO9)<=0),"",AO10/AO9)
A14: 재무상태표 (Balance sheet, 기말)
A15: 재고자산 (Inventories) | B15: 2889 | C15: 2750 | D15: 3000 | E15: 3064 | F15: 3123 | G15: 3160 | H15: 3184 | I15: 3369 | J15: 3595 | K15: 3876 | L15: 4390 | M15: 4905 | N15: 5118 | O15: 4943 | P15: 5208 | Q15: 5405 | R15: 5607 | S15: 5521 | T15: 4743 | U15: 4537 | V15: 4487 | W15: 4827 | X15: 5383 | Y15: 5629 | Z15: 6663 | AA15: 8359 | AB15: 8129 | AC15: 8238 | AD15: 8387 | AE15: 8276 | AF15: 8443 | AG15: 8512 | AH15: 8875 | AI15: 8705 | AJ15: 9007 | AK15: 8727 | AL15: 8355 | AM15: 8205 | AN15: 8267 | AO15: 8567
A16: 자산총계 (Total assets) | B16: 27540 | C16: 27836 | D16: 32355 | E16: 33267 | F16: 35336 | G16: 37191 | H16: 41263 | I16: 41845 | J16: 43376 | K16: 44595 | L16: 47487 | M16: 46288 | N16: 48887 | O16: 49649 | P16: 49648 | Q16: 52005 | R16: 53678 | S16: 53691 | T16: 54135 | U16: 55943 | V16: 58849 | W16: 61246 | X16: 63696 | Y16: 65296 | Z16: 66283 | AA16: 67874 | AB16: 66520 | AC16: 65680 | AD16: 64254 | AE16: 63776 | AF16: 65718 | AG16: 66255 | AH16: 69416 | AI16: 71461 | AJ16: 73053 | AK16: 78397 | AL16: 82798 | AM16: 85971 | AN16: 101509 | AO16: 134112
A18: 비율 (Ratios)
A19: Gross profit margin (영업이익 ÷ 매출액) | B19: =IF(OR(B8="",B6=""),"",B8/B6) | C19: =IF(OR(C8="",C6=""),"",C8/C6) | D19: =IF(OR(D8="",D6=""),"",D8/D6) | E19: =IF(OR(E8="",E6=""),"",E8/E6) | F19: =IF(OR(F8="",F6=""),"",F8/F6) | G19: =IF(OR(G8="",G6=""),"",G8/G6) | H19: =IF(OR(H8="",H6=""),"",H8/H6) | I19: =IF(OR(I8="",I6=""),"",I8/I6) | ... AO19: =IF(OR(AO8="",AO6=""),"",AO8/AO6)
A20: Profit margin (당기순이익 ÷ 매출액) | B20: =IF(OR(B9="",B6=""),"",B9/B6) | C20: =IF(OR(C9="",C6=""),"",C9/C6) | D20: =IF(OR(D9="",D6=""),"",D9/D6) | E20: =IF(OR(E9="",E6=""),"",E9/E6) | F20: =IF(OR(F9="",F6=""),"",F9/F6) | G20: =IF(OR(G9="",G6=""),"",G9/G6) | H20: =IF(OR(H9="",H6=""),"",H9/H6) | I20: =IF(OR(I9="",I6=""),"",I9/I6) | ... AO20: =IF(OR(AO9="",AO6=""),"",AO9/AO6)
A21: 재고자산 / 자산총계 (Inventory ÷ total assets) | B21: =IF(OR(B15="",B16=""),"",B15/B16) | C21: =IF(OR(C15="",C16=""),"",C15/C16) | D21: =IF(OR(D15="",D16=""),"",D15/D16) | E21: =IF(OR(E15="",E16=""),"",E15/E16) | F21: =IF(OR(F15="",F16=""),"",F15/F16) | G21: =IF(OR(G15="",G16=""),"",G15/G16) | H21: =IF(OR(H15="",H16=""),"",H15/H16) | I21: =IF(OR(I15="",I16=""),"",I15/I16) | ... AO21: =IF(OR(AO15="",AO16=""),"",AO15/AO16)
A22: 참고: 매출총이익률 (매출총이익 ÷ 매출액) | B22: =IF(OR(B7="",B6=""),"",B7/B6) | C22: =IF(OR(C7="",C6=""),"",C7/C6) | D22: =IF(OR(D7="",D6=""),"",D7/D6) | E22: =IF(OR(E7="",E6=""),"",E7/E6) | F22: =IF(OR(F7="",F6=""),"",F7/F6) | G22: =IF(OR(G7="",G6=""),"",G7/G6) | H22: =IF(OR(H7="",H6=""),"",H7/H6) | I22: =IF(OR(I7="",I6=""),"",I7/I6) | ... AO22: =IF(OR(AO7="",AO6=""),"",AO7/AO6)
A24: US$ 환산 (Converted to US$ millions)
A25: 적용환율 · 분기말 KRW/USD (FX rate applied) | B25: 1 | C25: 1 | D25: 1 | E25: 1 | F25: 1 | G25: 1 | H25: 1 | I25: 1 | J25: 1 | K25: 1 | L25: 1 | M25: 1 | N25: 1 | O25: 1 | P25: 1 | Q25: 1 | R25: 1 | S25: 1 | T25: 1 | U25: 1 | V25: 1 | W25: 1 | X25: 1 | Y25: 1 | Z25: 1 | AA25: 1 | AB25: 1 | AC25: 1 | AD25: 1 | AE25: 1 | AF25: 1 | AG25: 1 | AH25: 1 | AI25: 1 | AJ25: 1 | AK25: 1 | AL25: 1 | AM25: 1 | AN25: 1 | AO25: 1
A26: 재고자산 (Inventories, US$m) | B26: =IF(B15="","",B15) | C26: =IF(C15="","",C15) | D26: =IF(D15="","",D15) | E26: =IF(E15="","",E15) | F26: =IF(F15="","",F15) | G26: =IF(G15="","",G15) | H26: =IF(H15="","",H15) | I26: =IF(I15="","",I15) | ... AO26: =IF(AO15="","",AO15)
A27: 영업이익 (Operating income, US$m) | B27: =IF(B8="","",B8) | C27: =IF(C8="","",C8) | D27: =IF(D8="","",D8) | E27: =IF(E8="","",E8) | F27: =IF(F8="","",F8) | G27: =IF(G8="","",G8) | H27: =IF(H8="","",H8) | I27: =IF(I8="","",I8) | ... AO27: =IF(AO8="","",AO8)
A28: 시가총액 (Market cap, US$m) | B28: =IF(B10="","",B10) | C28: =IF(C10="","",C10) | D28: =IF(D10="","",D10) | E28: =IF(E10="","",E10) | F28: =IF(F10="","",F10) | G28: =IF(G10="","",G10) | H28: =IF(H10="","",H10) | I28: =IF(I10="","",I10) | ... AO28: =IF(AO10="","",AO10)

Sheet 그래프_연간
A1: 메모리 3사 연간 그래프 (Annual Charts, 2016~2025)
A2: 아래 데이터는 데이터 탭과 연결되어 있습니다. 원자료를 채우면 그래프도 함께 채워집니다.
A4: 차트용 데이터 (Chart data) | B4: 2016 | C4: 2017 | D4: 2018 | E4: 2019 | F4: 2020 | G4: 2021 | H4: 2022 | I4: 2023 | J4: 2024 | K4: 2025
A5: SK하이닉스 — 영업이익 (US$m) | B5: =연간_10년!B11 | C5: =연간_10년!C11 | D5: =연간_10년!D11 | E5: =연간_10년!E11 | F5: =연간_10년!F11 | G5: =연간_10년!G11 | H5: =연간_10년!H11 | I5: =연간_10년!I11 | ... K5: =연간_10년!K11
A6: SK하이닉스 — 재고자산 (US$m) | B6: =연간_10년!B14 | C6: =연간_10년!C14 | D6: =연간_10년!D14 | E6: =연간_10년!E14 | F6: =연간_10년!F14 | G6: =연간_10년!G14 | H6: =연간_10년!H14 | I6: =연간_10년!I14 | ... K6: =연간_10년!K14
A7: SK하이닉스 — Gross profit margin | B7: =연간_10년!B17 | C7: =연간_10년!C17 | D7: =연간_10년!D17 | E7: =연간_10년!E17 | F7: =연간_10년!F17 | G7: =연간_10년!G17 | H7: =연간_10년!H17 | I7: =연간_10년!I17 | ... K7: =연간_10년!K17
A8: SK하이닉스 — PE ratio | B8: =연간_10년!B19 | C8: =연간_10년!C19 | D8: =연간_10년!D19 | E8: =연간_10년!E19 | F8: =연간_10년!F19 | G8: =연간_10년!G19 | H8: =연간_10년!H19 | I8: =연간_10년!I19 | ... K8: =연간_10년!K19
A9: 삼성전자 — 영업이익 (US$m) | B9: =연간_10년!M11 | C9: =연간_10년!N11 | D9: =연간_10년!O11 | E9: =연간_10년!P11 | F9: =연간_10년!Q11 | G9: =연간_10년!R11 | H9: =연간_10년!S11 | I9: =연간_10년!T11 | ... K9: =연간_10년!V11
A10: 삼성전자 — 재고자산 (US$m) | B10: =연간_10년!M14 | C10: =연간_10년!N14 | D10: =연간_10년!O14 | E10: =연간_10년!P14 | F10: =연간_10년!Q14 | G10: =연간_10년!R14 | H10: =연간_10년!S14 | I10: =연간_10년!T14 | ... K10: =연간_10년!V14
A11: 삼성전자 — Gross profit margin | B11: =연간_10년!M17 | C11: =연간_10년!N17 | D11: =연간_10년!O17 | E11: =연간_10년!P17 | F11: =연간_10년!Q17 | G11: =연간_10년!R17 | H11: =연간_10년!S17 | I11: =연간_10년!T17 | ... K11: =연간_10년!V17
A12: 삼성전자 — PE ratio | B12: =연간_10년!M19 | C12: =연간_10년!N19 | D12: =연간_10년!O19 | E12: =연간_10년!P19 | F12: =연간_10년!Q19 | G12: =연간_10년!R19 | H12: =연간_10년!S19 | I12: =연간_10년!T19 | ... K12: =연간_10년!V19
A13: 마이크론 — 영업이익 (US$m) | B13: =연간_10년!X11 | C13: =연간_10년!Y11 | D13: =연간_10년!Z11 | E13: =연간_10년!AA11 | F13: =연간_10년!AB11 | G13: =연간_10년!AC11 | H13: =연간_10년!AD11 | I13: =연간_10년!AE11 | ... K13: =연간_10년!AG11
A14: 마이크론 — 재고자산 (US$m) | B14: =연간_10년!X14 | C14: =연간_10년!Y14 | D14: =연간_10년!Z14 | E14: =연간_10년!AA14 | F14: =연간_10년!AB14 | G14: =연간_10년!AC14 | H14: =연간_10년!AD14 | I14: =연간_10년!AE14 | ... K14: =연간_10년!AG14
A15: 마이크론 — Gross profit margin | B15: =연간_10년!X17 | C15: =연간_10년!Y17 | D15: =연간_10년!Z17 | E15: =연간_10년!AA17 | F15: =연간_10년!AB17 | G15: =연간_10년!AC17 | H15: =연간_10년!AD17 | I15: =연간_10년!AE17 | ... K15: =연간_10년!AG17
A16: 마이크론 — PE ratio | B16: =연간_10년!X19 | C16: =연간_10년!Y19 | D16: =연간_10년!Z19 | E16: =연간_10년!AA19 | F16: =연간_10년!AB19 | G16: =연간_10년!AC19 | H16: =연간_10년!AD19 | I16: =연간_10년!AE19 | ... K16: =연간_10년!AG19
A18: 3사 비교 블록 (All three companies) | B18: 2016 | C18: 2017 | D18: 2018 | E18: 2019 | F18: 2020 | G18: 2021 | H18: 2022 | I18: 2023 | J18: 2024 | K18: 2025
A19: SK하이닉스 — Gross profit margin | B19: =B7 | C19: =C7 | D19: =D7 | E19: =E7 | F19: =F7 | G19: =G7 | H19: =H7 | I19: =I7 | ... K19: =K7
A20: 삼성전자 — Gross profit margin | B20: =B11 | C20: =C11 | D20: =D11 | E20: =E11 | F20: =F11 | G20: =G11 | H20: =H11 | I20: =I11 | ... K20: =K11
A21: 마이크론 — Gross profit margin | B21: =B15 | C21: =C15 | D21: =D15 | E21: =E15 | F21: =F15 | G21: =G15 | H21: =H15 | I21: =I15 | ... K21: =K15
A23: SK하이닉스 — 재고자산 (US$m) | B23: =B6 | C23: =C6 | D23: =D6 | E23: =E6 | F23: =F6 | G23: =G6 | H23: =H6 | I23: =I6 | ... K23: =K6
A24: 삼성전자 — 재고자산 (US$m) | B24: =B10 | C24: =C10 | D24: =D10 | E24: =E10 | F24: =F10 | G24: =G10 | H24: =H10 | I24: =I10 | ... K24: =K10
A25: 마이크론 — 재고자산 (US$m) | B25: =B14 | C25: =C14 | D25: =D14 | E25: =E14 | F25: =F14 | G25: =G14 | H25: =H14 | I25: =I14 | ... K25: =K14
A27: SK하이닉스 — PE ratio | B27: =B8 | C27: =C8 | D27: =D8 | E27: =E8 | F27: =F8 | G27: =G8 | H27: =H8 | I27: =I8 | ... K27: =K8
A28: 삼성전자 — PE ratio | B28: =B12 | C28: =C12 | D28: =D12 | E28: =E12 | F28: =F12 | G28: =G12 | H28: =H12 | I28: =I12 | ... K28: =K12
A29: 마이크론 — PE ratio | B29: =B16 | C29: =C16 | D29: =D16 | E29: =E16 | F29: =F16 | G29: =G16 | H29: =H16 | I29: =I16 | ... K29: =K16

Sheet 그래프_분기
A1: 메모리 3사 분기 그래프 (Quarterly Charts, 2016Q3~2026Q2)
A2: 아래 데이터는 데이터 탭과 연결되어 있습니다. 원자료를 채우면 그래프도 함께 채워집니다.
A4: 차트용 데이터 (Chart data) | B4: 2021Q3 | C4: 2021Q4 | D4: 2022Q1 | E4: 2022Q2 | F4: 2022Q3 | G4: 2022Q4 | H4: 2023Q1 | I4: 2023Q2 | J4: 2023Q3 | K4: 2023Q4 | L4: 2024Q1 | M4: 2024Q2 | N4: 2024Q3 | O4: 2024Q4 | P4: 2025Q1 | Q4: 2025Q2 | R4: 2025Q3 | S4: 2025Q4 | T4: 2026Q1 | U4: 2026Q2
A5: SK하이닉스 — 영업이익 (US$m) | B5: =SK하이닉스_분기!B27 | C5: =SK하이닉스_분기!C27 | D5: =SK하이닉스_분기!D27 | E5: =SK하이닉스_분기!E27 | F5: =SK하이닉스_분기!F27 | G5: =SK하이닉스_분기!G27 | H5: =SK하이닉스_분기!H27 | I5: =SK하이닉스_분기!I27 | ... U5: =SK하이닉스_분기!U27
A6: SK하이닉스 — 재고자산 (US$m) | B6: =SK하이닉스_분기!B26 | C6: =SK하이닉스_분기!C26 | D6: =SK하이닉스_분기!D26 | E6: =SK하이닉스_분기!E26 | F6: =SK하이닉스_분기!F26 | G6: =SK하이닉스_분기!G26 | H6: =SK하이닉스_분기!H26 | I6: =SK하이닉스_분기!I26 | ... U6: =SK하이닉스_분기!U26
A7: SK하이닉스 — Gross profit margin | B7: =SK하이닉스_분기!B19 | C7: =SK하이닉스_분기!C19 | D7: =SK하이닉스_분기!D19 | E7: =SK하이닉스_분기!E19 | F7: =SK하이닉스_분기!F19 | G7: =SK하이닉스_분기!G19 | H7: =SK하이닉스_분기!H19 | I7: =SK하이닉스_분기!I19 | ... U7: =SK하이닉스_분기!U19
A8: SK하이닉스 — PE ratio | B8: =SK하이닉스_분기!B11 | C8: =SK하이닉스_분기!C11 | D8: =SK하이닉스_분기!D11 | E8: =SK하이닉스_분기!E11 | F8: =SK하이닉스_분기!F11 | G8: =SK하이닉스_분기!G11 | H8: =SK하이닉스_분기!H11 | I8: =SK하이닉스_분기!I11 | ... U8: =SK하이닉스_분기!U11
A9: 삼성전자 — 영업이익 (US$m) | B9: =삼성전자_분기!B27 | C9: =삼성전자_분기!C27 | D9: =삼성전자_분기!D27 | E9: =삼성전자_분기!E27 | F9: =삼성전자_분기!F27 | G9: =삼성전자_분기!G27 | H9: =삼성전자_분기!H27 | I9: =삼성전자_분기!I27 | ... U9: =삼성전자_분기!U27
A10: 삼성전자 — 재고자산 (US$m) | B10: =삼성전자_분기!B26 | C10: =삼성전자_분기!C26 | D10: =삼성전자_분기!D26 | E10: =삼성전자_분기!E26 | F10: =삼성전자_분기!F26 | G10: =삼성전자_분기!G26 | H10: =삼성전자_분기!H26 | I10: =삼성전자_분기!I26 | ... U10: =삼성전자_분기!U26
A11: 삼성전자 — Gross profit margin | B11: =삼성전자_분기!B19 | C11: =삼성전자_분기!C19 | D11: =삼성전자_분기!D19 | E11: =삼성전자_분기!E19 | F11: =삼성전자_분기!F19 | G11: =삼성전자_분기!G19 | H11: =삼성전자_분기!H19 | I11: =삼성전자_분기!I19 | ... U11: =삼성전자_분기!U19
A12: 삼성전자 — PE ratio | B12: =삼성전자_분기!B11 | C12: =삼성전자_분기!C11 | D12: =삼성전자_분기!D11 | E12: =삼성전자_분기!E11 | F12: =삼성전자_분기!F11 | G12: =삼성전자_분기!G11 | H12: =삼성전자_분기!H11 | I12: =삼성전자_분기!I11 | ... U12: =삼성전자_분기!U11
A13: 마이크론 — 영업이익 (US$m) | B13: =마이크론_분기!V27 | C13: =마이크론_분기!W27 | D13: =마이크론_분기!X27 | E13: =마이크론_분기!Y27 | F13: =마이크론_분기!Z27 | G13: =마이크론_분기!AA27 | H13: =마이크론_분기!AB27 | I13: =마이크론_분기!AC27 | ... U13: =마이크론_분기!AO27
A14: 마이크론 — 재고자산 (US$m) | B14: =마이크론_분기!V26 | C14: =마이크론_분기!W26 | D14: =마이크론_분기!X26 | E14: =마이크론_분기!Y26 | F14: =마이크론_분기!Z26 | G14: =마이크론_분기!AA26 | H14: =마이크론_분기!AB26 | I14: =마이크론_분기!AC26 | ... U14: =마이크론_분기!AO26
A15: 마이크론 — Gross profit margin | B15: =마이크론_분기!V19 | C15: =마이크론_분기!W19 | D15: =마이크론_분기!X19 | E15: =마이크론_분기!Y19 | F15: =마이크론_분기!Z19 | G15: =마이크론_분기!AA19 | H15: =마이크론_분기!AB19 | I15: =마이크론_분기!AC19 | ... U15: =마이크론_분기!AO19
A16: 마이크론 — PE ratio | B16: =마이크론_분기!V11 | C16: =마이크론_분기!W11 | D16: =마이크론_분기!X11 | E16: =마이크론_분기!Y11 | F16: =마이크론_분기!Z11 | G16: =마이크론_분기!AA11 | H16: =마이크론_분기!AB11 | I16: =마이크론_분기!AC11 | ... U16: =마이크론_분기!AO11
A18: 3사 비교 블록 (All three companies) | B18: 2021Q3 | C18: 2021Q4 | D18: 2022Q1 | E18: 2022Q2 | F18: 2022Q3 | G18: 2022Q4 | H18: 2023Q1 | I18: 2023Q2 | J18: 2023Q3 | K18: 2023Q4 | L18: 2024Q1 | M18: 2024Q2 | N18: 2024Q3 | O18: 2024Q4 | P18: 2025Q1 | Q18: 2025Q2 | R18: 2025Q3 | S18: 2025Q4 | T18: 2026Q1 | U18: 2026Q2
A19: SK하이닉스 — Gross profit margin | B19: =B7 | C19: =C7 | D19: =D7 | E19: =E7 | F19: =F7 | G19: =G7 | H19: =H7 | I19: =I7 | ... U19: =U7
A20: 삼성전자 — Gross profit margin | B20: =B11 | C20: =C11 | D20: =D11 | E20: =E11 | F20: =F11 | G20: =G11 | H20: =H11 | I20: =I11 | ... U20: =U11
A21: 마이크론 — Gross profit margin | B21: =B15 | C21: =C15 | D21: =D15 | E21: =E15 | F21: =F15 | G21: =G15 | H21: =H15 | I21: =I15 | ... U21: =U15
A23: SK하이닉스 — 재고자산 (US$m) | B23: =B6 | C23: =C6 | D23: =D6 | E23: =E6 | F23: =F6 | G23: =G6 | H23: =H6 | I23: =I6 | ... U23: =U6
A24: 삼성전자 — 재고자산 (US$m) | B24: =B10 | C24: =C10 | D24: =D10 | E24: =E10 | F24: =F10 | G24: =G10 | H24: =H10 | I24: =I10 | ... U24: =U10
A25: 마이크론 — 재고자산 (US$m) | B25: =B14 | C25: =C14 | D25: =D14 | E25: =E14 | F25: =F14 | G25: =G14 | H25: =H14 | I25: =I14 | ... U25: =U14
A27: SK하이닉스 — PE ratio | B27: =B8 | C27: =C8 | D27: =D8 | E27: =E8 | F27: =F8 | G27: =G8 | H27: =H8 | I27: =I8 | ... U27: =U8
A28: 삼성전자 — PE ratio | B28: =B12 | C28: =C12 | D28: =D12 | E28: =E12 | F28: =F12 | G28: =G12 | H28: =H12 | I28: =I12 | ... U28: =U12
A29: 마이크론 — PE ratio | B29: =B16 | C29: =C16 | D29: =D16 | E29: =E16 | F29: =F16 | G29: =G16 | H29: =H16 | I29: =I16 | ... U29: =U16

Sheet 그래프_GPM_3사
A1: 메모리 3사 Gross Profit Margin 비교 — 분기 (Memory Big 3 — Quarterly Gross Profit Margin)
A2: 정의: Gross profit margin = 영업이익 ÷ 매출액 (이 워크북 전체에서 쓰는 정의. 교과서상 매출총이익률은 아래 «참고» 표에 있습니다.)
A3: 기간: 2021Q3~2026Q2 (20개 분기) — 3사가 모두 채워져 있는 공통 구간입니다. 마이크론은 2016Q3부터 있으나 한국 2사는 2021Q3부터라 비교 구간을 여기에 맞췄습니다.
A4: 주의: 마이크론 회계연도는 8~9월 종료 — 한국 2사(12월 결산)와 정확히 같은 기간이 아닙니다. 분기 라벨은 달력 분기 기준으로 맞춘 것입니다.
A6: Gross profit margin (영업이익 ÷ 매출액) — 그래프에 그려진 값
A7: 항목 (Metric) | B7: 2021Q3 | C7: 2021Q4 | D7: 2022Q1 | E7: 2022Q2 | F7: 2022Q3 | G7: 2022Q4 | H7: 2023Q1 | I7: 2023Q2 | J7: 2023Q3 | K7: 2023Q4 | L7: 2024Q1 | M7: 2024Q2 | N7: 2024Q3 | O7: 2024Q4 | P7: 2025Q1 | Q7: 2025Q2 | R7: 2025Q3 | S7: 2025Q4 | T7: 2026Q1 | U7: 2026Q2
A8: 삼성전자 (Samsung Electronics) | B8: ='삼성전자_분기'!B19 | C8: ='삼성전자_분기'!C19 | D8: ='삼성전자_분기'!D19 | E8: ='삼성전자_분기'!E19 | F8: ='삼성전자_분기'!F19 | G8: ='삼성전자_분기'!G19 | H8: ='삼성전자_분기'!H19 | I8: ='삼성전자_분기'!I19 | ... U8: ='삼성전자_분기'!U19
A9: SK하이닉스 (SK hynix) | B9: ='SK하이닉스_분기'!B19 | C9: ='SK하이닉스_분기'!C19 | D9: ='SK하이닉스_분기'!D19 | E9: ='SK하이닉스_분기'!E19 | F9: ='SK하이닉스_분기'!F19 | G9: ='SK하이닉스_분기'!G19 | H9: ='SK하이닉스_분기'!H19 | I9: ='SK하이닉스_분기'!I19 | ... U9: ='SK하이닉스_분기'!U19
A10: 마이크론 (Micron Technology) | B10: ='마이크론_분기'!V19 | C10: ='마이크론_분기'!W19 | D10: ='마이크론_분기'!X19 | E10: ='마이크론_분기'!Y19 | F10: ='마이크론_분기'!Z19 | G10: ='마이크론_분기'!AA19 | H10: ='마이크론_분기'!AB19 | I10: ='마이크론_분기'!AC19 | ... U10: ='마이크론_분기'!AO19
A12: 참고: 교과서상 매출총이익률 (매출총이익 ÷ 매출액) | F12: 참고용 — 그래프에는 포함되지 않았습니다.
A13: 항목 (Metric) | B13: 2021Q3 | C13: 2021Q4 | D13: 2022Q1 | E13: 2022Q2 | F13: 2022Q3 | G13: 2022Q4 | H13: 2023Q1 | I13: 2023Q2 | J13: 2023Q3 | K13: 2023Q4 | L13: 2024Q1 | M13: 2024Q2 | N13: 2024Q3 | O13: 2024Q4 | P13: 2025Q1 | Q13: 2025Q2 | R13: 2025Q3 | S13: 2025Q4 | T13: 2026Q1 | U13: 2026Q2
A14: 삼성전자 (Samsung Electronics) | B14: ='삼성전자_분기'!B22 | C14: ='삼성전자_분기'!C22 | D14: ='삼성전자_분기'!D22 | E14: ='삼성전자_분기'!E22 | F14: ='삼성전자_분기'!F22 | G14: ='삼성전자_분기'!G22 | H14: ='삼성전자_분기'!H22 | I14: ='삼성전자_분기'!I22 | ... U14: ='삼성전자_분기'!U22
A15: SK하이닉스 (SK hynix) | B15: ='SK하이닉스_분기'!B22 | C15: ='SK하이닉스_분기'!C22 | D15: ='SK하이닉스_분기'!D22 | E15: ='SK하이닉스_분기'!E22 | F15: ='SK하이닉스_분기'!F22 | G15: ='SK하이닉스_분기'!G22 | H15: ='SK하이닉스_분기'!H22 | I15: ='SK하이닉스_분기'!I22 | ... U15: ='SK하이닉스_분기'!U22
A16: 마이크론 (Micron Technology) | B16: ='마이크론_분기'!V22 | C16: ='마이크론_분기'!W22 | D16: ='마이크론_분기'!X22 | E16: ='마이크론_분기'!Y22 | F16: ='마이크론_분기'!Z22 | G16: ='마이크론_분기'!AA22 | H16: ='마이크론_분기'!AB22 | I16: ='마이크론_분기'!AC22 | ... U16: ='마이크론_분기'!AO22
A17: 초록색 = 다른 시트를 참조하는 수식입니다. 원 데이터를 고치면 이 표와 그래프가 자동으로 따라갑니다 (각 회사의 «_분기» 시트 19행·22행).
