Workbook

Sheet README
A1: FCFF 기업가치평가 강의자료 — SK hynix · NVIDIA
A2: 2026년 8월 5일 작성 · KAIST 경영대학
A4: 이 워크북의 구성
A5: Raw_NVDA | B5: NVIDIA: FCFF 산출에 필요한 10개 회계연도(FY2017~FY2026) 항목
A6: Raw_SKhynix | B6: SK hynix: 동일한 양식의 10개 사업연도(2016~2025) 항목
A7: Raw_Quarterly | B7: 각 기업의 최근 5개 분기 실적. 중간기간 논의용.
A8: Consensus | B8: 증권사 컨센서스 추정치(기업 단위)와 출처
A9: Val_NVDA | B9: NVIDIA: FCFF → 기업가치 → 자기자본가치 → 주당가치
A10: Val_SKhynix | B10: SK hynix에 동일한 모형을 원화 기준으로 적용
A12: 색상 규칙 (재무모형 표준 관행)
A13: 파란색 글씨 | B13: 직접 입력한 값 또는 가정. 학생들이 바꿔가며 실습할 셀입니다.
A14: 검은색 글씨 | B14: 같은 시트 안에서 계산되는 수식
A15: 초록색 글씨 | B15: 이 워크북의 다른 시트를 참조하는 수식
A16: 노란색 음영 | B16: 핵심 가정 — 결과를 좌우하는 변수. 수업에서 가장 먼저 조정해 볼 셀입니다.
A18: 데이터 출처 — 반드시 확인
A19: Tier A | B19: 2026년 8월 5일 SEC EDGAR에서 조회한 1차 공시자료에서 직접 인용. 그대로 사용 가능.
A20: Tier B | B20: 기업 IR 보도자료. 신뢰할 수 있으나 1차 자료를 재가공한 2차 자료.
A21: Tier C | B21: 원문을 재조회하지 않고 과거 공시자료에서 정리한 수치. 학생 배포 전 10-K(NVIDIA) 또는 DART 사업보고서(SK hynix)와 반드시 대조 확인 바랍니다.
B22: 원자료 탭의 각 연도에는 맨 아래 행에 출처 등급이 표시되어 있습니다. 요약하면 NVIDIA는 최근 2개 연도, SK hynix는 최근 3개 연도가 Tier A이며 그 이전 연도는 Tier C입니다.
A24: 학생들에게 먼저 짚어줄 사항
A25: 두 기업의 회계연도는 일치하지 않는다 | B25: NVIDIA의 FY2026은 2026년 1월 25일에, SK hynix의 2025년은 2025년 12월 31일에 종료되었습니다. 두 열은 약 한 달 차이가 있으며 동일한 기간이 아니므로 같은 기간처럼 제시해서는 안 됩니다.
A26: 공시된 자본적지출은 현금흐름표의 개별 항목이며 투자활동현금흐름 전체가 아니다 | B26: 투자활동현금흐름에는 자본적지출 외에 유가증권 취득, 사업결합, 지분투자가 함께 포함됩니다. 두 기업 모두 자본적지출을 별도로 공시합니다. NVIDIA는 유형자산 및 무형자산 취득으로, SK hynix는 증권신고서상 유형자산 취득 관련 현금유출로 표시하며, 본 자료는 이 수치를 사용했습니다.
A27: 두 기업 모두 최근 연도는 교과서적인 사례가 아니다 | B27: NVIDIA의 FY2026 당기순이익에는 지분증권 처분이익 89억 달러가 포함되어 있고, SK hynix의 2026년 2분기 당기순이익 93.9조 원은 Kioxia 지분 매각이익 때문에 매출액을 초과합니다. FCFF를 당기순이익이 아니라 영업이익과 영업활동현금흐름에서 출발시키는 이유가 바로 여기에 있습니다.
A29: 1차 출처
A30: NVIDIA FY2026(4분기) 실적 — 손익계산서·재무상태표·현금흐름표 전문 포함 | B30: https://www.sec.gov/Archives/edgar/data/1045810/000104581026000019/q4fy26pr.htm
A31: NVIDIA FY2027 1분기 실적 — 손익계산서·재무상태표·현금흐름표 전문 포함 | B31: https://www.sec.gov/Archives/edgar/data/1045810/000104581026000051/q1fy27pr.htm
A32: SK hynix Form 424B4 증권신고서 (IFRS 감사받은 2023~2025년 및 2026년 1분기) | B32: https://www.sec.gov/Archives/edgar/data/2120882/000119312526299963/d32785d424b4.htm
A33: SK hynix FY2025 실적 보도자료 | B33: https://news.skhynix.com/en/sk-hynix-announces-fy25-financial-results/
A34: SK hynix 2026년 2분기 실적 보도자료 | B34: https://news.skhynix.com/en/q2-2026-business-results/
A35: SK hynix 자본적지출 추이 2021~2025 | B35: https://finbox.com/KOSE:A000660/explorer/capex/

Sheet Raw_NVDA
A1: NVIDIA Corporation — 10개년 FCFF 입력자료
A2: 단위: 백만 달러(US$mm). 회계연도는 1월 마지막 일요일 종료 (FY2026 = 2026년 1월 25일 종료).
A4: 회계연도 (Fiscal year) | B4: 2017 | C4: 2018 | D4: 2019 | E4: 2020 | F4: 2021 | G4: 2022 | H4: 2023 | I4: 2024 | J4: 2025 | K4: 2026 | L4: 등급 (Tier) | M4: 비고 (Note)
A5: 손익계산서
A6: 매출액 (Revenue) | B6: 6910 | C6: 9714 | D6: 11716 | E6: 10918 | F6: 16675 | G6: 26914 | H6: 26974 | I6: 60922 | J6: 130497 | K6: 215938
A7: 매출총이익 (Gross profit) | B7: 4063 | C7: 5822 | D7: 7171 | E7: 6768 | F7: 10396 | G7: 17475 | H7: 15356 | I7: 44301 | J7: 97858 | K7: 153463
A8: 영업비용 합계 (Total operating expenses) | B8: 2129 | C8: 2612 | D8: 3367 | E8: 3922 | F8: 5864 | G8: 7434 | H8: 11132 | I8: 11329 | J8: 16405 | K8: 23076
A9: 영업이익 (Operating income (EBIT)) | B9: 1934 | C9: 3210 | D9: 3804 | E9: 2846 | F9: 4532 | G9: 10041 | H9: 4224 | I9: 32972 | J9: 81453 | K9: 130387
A10: 이자비용 (Interest expense) | B10: 58 | C10: 61 | D10: 58 | E10: 52 | F10: 184 | G10: 236 | H10: 262 | I10: 257 | J10: 247 | K10: 259 | M10: FCFF에서 가산하는 항목. IFRS 적용기업은 분류가 다를 수 있습니다.
A11: 법인세비용차감전순이익 (Pre-tax income) | B11: 1905 | C11: 3195 | D11: 3896 | E11: 2970 | F11: 4409 | G11: 11259 | H11: 4181 | I11: 33818 | J11: 84026 | K11: 141450
A12: 법인세비용 (Income tax expense) | B12: 239 | C12: 149 | D12: -245 | E12: 174 | F12: 77 | G12: 1507 | H12: -187 | I12: 4058 | J12: 11146 | K12: 21383
A13: 당기순이익 (Net income) | B13: 1666 | C13: 3047 | D13: 4141 | E13: 2796 | F13: 4332 | G13: 9752 | H13: 4368 | I13: 29760 | J13: 72880 | K13: 120067
A15: 현금흐름표
A16: 영업활동현금흐름 (Cash flow from operations (CFO)) | B16: 1672 | C16: 3502 | D16: 3743 | E16: 4761 | F16: 5822 | G16: 9108 | H16: 5641 | I16: 28090 | J16: 64089 | K16: 102718
A17: 자본적지출 (Capital expenditures) | B17: 176 | C17: 593 | D17: 600 | E17: 489 | F17: 1128 | G17: 976 | H17: 1833 | I17: 1069 | J17: 3236 | K17: 6042 | M17: 공시된 자본적지출 항목만 반영 — 투자활동 내 유가증권 취득과 사업결합은 제외.
A18: 감가상각비·무형자산상각비 (Depreciation & amortisation) | B18: 187 | C18: 199 | D18: 262 | E18: 381 | F18: 1098 | G18: 1174 | H18: 1544 | I18: 1508 | J18: 1864 | K18: 2843
A19: 주식기준보상비용 (Stock-based compensation) | B19: 557 | C19: 391 | D19: 557 | E19: 844 | F19: 1397 | G19: 2004 | H19: 2709 | I19: 3549 | J19: 4737 | K19: 6386 | M19: 비현금항목으로 이미 영업활동현금흐름에 포함. FCFF는 비용이 들지 않는 것으로 보지만 주주 입장은 그렇지 않다는 점을 짚어줄 필요가 있습니다.
A21: 재무상태표 (기말)
A22: 자산총계 (Total assets) | B22: 9841 | C22: 11241 | D22: 13292 | E22: 17315 | F22: 28791 | G22: 44187 | H22: 41182 | I22: 65728 | J22: 111601 | K22: 206803
A23: 현금및유가증권 (Cash & marketable securities) | B23: 6798 | C23: 7108 | D23: 7422 | E23: 10896 | F23: 11561 | G23: 21208 | H23: 13296 | I23: 25984 | J23: 43210 | K23: 62556
A24: 단기차입금 (Short-term borrowings) | B24: 15 | C24: 0 | D24: 0 | E24: 0 | F24: 999 | G24: 0 | H24: 1250 | I24: 1250 | J24: 0 | K24: 999
A25: 장기차입금 (Long-term borrowings) | B25: 1985 | C25: 1985 | D25: 1988 | E25: 1991 | F25: 5964 | G25: 10946 | H25: 9703 | I25: 8459 | J25: 8463 | K25: 7469
A26: 총차입금 (Total debt) | B26: =B24+B25 -> 2000 | C26: =C24+C25 -> 1985 | D26: =D24+D25 -> 1988 | E26: =E24+E25 -> 1991 | F26: =F24+F25 -> 6963 | G26: =G24+G25 -> 10946 | H26: =H24+H25 -> 10953 | I26: =I24+I25 -> 9709 | ... K26: =K24+K25 -> 8468
A27: 순차입금(순현금) (Net debt (cash)) | B27: =B26-B23 -> -4798 | C27: =C26-C23 -> -5123 | D27: =D26-D23 -> -5434 | E27: =E26-E23 -> -8905 | F27: =F26-F23 -> -4598 | G27: =G26-G23 -> -10262 | H27: =H26-H23 -> -2343 | I27: =I26-I23 -> -16275 | ... K27: =K26-K23 -> -54088
A28: 자본총계 (Total equity) | B28: 5762 | C28: 7471 | D28: 9342 | E28: 12204 | F28: 16893 | G28: 26612 | H28: 22101 | I28: 42978 | J28: 79327 | K28: 157293
A29: 발행주식수 (Shares outstanding (m)) | B29: 1000 | C29: 649 | D29: 625 | E29: 616 | F29: 628 | G29: 636 | H29: 618 | I29: 24690 | J29: 24804 | K29: 24514
A31: 산출 비율 — 전부 수식이며 직접 입력한 값 없음
A32: 매출액 증가율 (Revenue growth) | C32: =IF(B6=0,"",C6/B6-1) -> 0.40578871 | D32: =IF(C6=0,"",D6/C6-1) -> 0.2060943 | E32: =IF(D6=0,"",E6/D6-1) -> -0.068111984 | F32: =IF(E6=0,"",F6/E6-1) -> 0.52729438 | G32: =IF(F6=0,"",G6/F6-1) -> 0.61403298 | H32: =IF(G6=0,"",H6/G6-1) -> 0.002229323 | I32: =IF(H6=0,"",I6/H6-1) -> 1.2585453 | J32: =IF(I6=0,"",J6/I6-1) -> 1.1420341 | K32: =IF(J6=0,"",K6/J6-1) -> 0.65473536
A33: 영업이익률 (Operating margin) | B33: =IF(B6=0,"",B9/B6) -> 0.27988423 | C33: =IF(C6=0,"",C9/C6) -> 0.3304509 | D33: =IF(D6=0,"",D9/D6) -> 0.32468419 | E33: =IF(E6=0,"",E9/E6) -> 0.26067045 | F33: =IF(F6=0,"",F9/F6) -> 0.27178411 | G33: =IF(G6=0,"",G9/G6) -> 0.37307721 | H33: =IF(H6=0,"",H9/H6) -> 0.15659524 | I33: =IF(I6=0,"",I9/I6) -> 0.54121664 | ... K33: =IF(K6=0,"",K9/K6) -> 0.60381684
A34: 순이익률 (Net margin) | B34: =IF(B6=0,"",B13/B6) -> 0.24109986 | C34: =IF(C6=0,"",C13/C6) -> 0.31367099 | D34: =IF(D6=0,"",D13/D6) -> 0.35344828 | E34: =IF(E6=0,"",E13/E6) -> 0.25609086 | F34: =IF(F6=0,"",F13/F6) -> 0.2597901 | G34: =IF(G6=0,"",G13/G6) -> 0.3623393 | H34: =IF(H6=0,"",H13/H6) -> 0.16193371 | I34: =IF(I6=0,"",I13/I6) -> 0.48849348 | ... K34: =IF(K6=0,"",K13/K6) -> 0.55602534
A35: 유효법인세율 (Effective tax rate) | B35: =IFERROR(B12/B11,"") -> 0.12545932 | C35: =IFERROR(C12/C11,"") -> 0.046635368 | D35: =IFERROR(D12/D11,"") -> -0.06288501 | E35: =IFERROR(E12/E11,"") -> 0.058585859 | F35: =IFERROR(F12/F11,"") -> 0.017464278 | G35: =IFERROR(G12/G11,"") -> 0.13384848 | H35: =IFERROR(H12/H11,"") -> -0.044726142 | I35: =IFERROR(I12/I11,"") -> 0.11999527 | ... K35: =IFERROR(K12/K11,"") -> 0.15117002 | M35: 결손 연도에는 음수나 비정상적 값이 나타납니다. 모형에서 정상화 세율을 쓰는 이유입니다.
A36: 자본적지출/매출액 (Capex / revenue) | B36: =IF(B6=0,"",B17/B6) -> 0.025470333 | C36: =IF(C6=0,"",C17/C6) -> 0.061045913 | D36: =IF(D6=0,"",D17/D6) -> 0.051212018 | E36: =IF(E6=0,"",E17/E6) -> 0.044788423 | F36: =IF(F6=0,"",F17/F6) -> 0.067646177 | G36: =IF(G6=0,"",G17/G6) -> 0.036263655 | H36: =IF(H6=0,"",H17/H6) -> 0.067954326 | I36: =IF(I6=0,"",I17/I6) -> 0.017547027 | ... K36: =IF(K6=0,"",K17/K6) -> 0.027980254
A37: 자본적지출/감가상각비 (Capex / D&A) | B37: =IFERROR(B17/B18,"") -> 0.94117647 | C37: =IFERROR(C17/C18,"") -> 2.9798995 | D37: =IFERROR(D17/D18,"") -> 2.2900763 | E37: =IFERROR(E17/E18,"") -> 1.2834646 | F37: =IFERROR(F17/F18,"") -> 1.0273224 | G37: =IFERROR(G17/G18,"") -> 0.83134583 | H37: =IFERROR(H17/H18,"") -> 1.1871762 | I37: =IFERROR(I17/I18,"") -> 0.70888594 | ... K37: =IFERROR(K17/K18,"") -> 2.1252198 | M37: 1.0배를 넘으면 자산을 유지하는 수준을 넘어 확장하고 있다는 뜻입니다.
A39: FCFF 산출 — FCFF = 영업활동현금흐름 + 이자비용 x (1 - t) - 자본적지출
A40: 적용 법인세율(정상화) (Normalised tax rate used) | B40: 0.21 | C40: 0.21 | D40: 0.21 | E40: 0.21 | F40: 0.21 | G40: 0.21 | H40: 0.21 | I40: 0.21 | J40: 0.21 | K40: 0.21 | M40: 법정세율에 준하는 값. 자유롭게 수정하십시오. 이자 절세효과가 FCFF를 실제로 얼마나 적게 움직이는지 보여주는 셀입니다.
A41: 이자비용 x (1 - t) (Interest x (1 - t)) | B41: =B10*(1-B40) -> 45.82 | C41: =C10*(1-C40) -> 48.19 | D41: =D10*(1-D40) -> 45.82 | E41: =E10*(1-E40) -> 41.08 | F41: =F10*(1-F40) -> 145.36 | G41: =G10*(1-G40) -> 186.44 | H41: =H10*(1-H40) -> 206.98 | I41: =I10*(1-I40) -> 203.03 | ... K41: =K10*(1-K40) -> 204.61
A42: 기업잉여현금흐름 (FCFF) | B42: =B16+B41-B17 -> 1541.82 | C42: =C16+C41-C17 -> 2957.19 | D42: =D16+D41-D17 -> 3188.82 | E42: =E16+E41-E17 -> 4313.08 | F42: =F16+F41-F17 -> 4839.36 | G42: =G16+G41-G17 -> 8318.44 | H42: =H16+H41-H17 -> 4014.98 | I42: =I16+I41-I17 -> 27224.03 | ... K42: =K16+K41-K17 -> 96880.61
A43: FCFF 마진 (FCFF margin) | B43: =IF(B6=0,"",B42/B6) -> 0.2231288 | C43: =IF(C6=0,"",C42/C6) -> 0.30442557 | D43: =IF(D6=0,"",D42/D6) -> 0.27217651 | E43: =IF(E6=0,"",E42/E6) -> 0.39504305 | F43: =IF(F6=0,"",F42/F6) -> 0.29021649 | G43: =IF(G6=0,"",G42/G6) -> 0.30907483 | H43: =IF(H6=0,"",H42/H6) -> 0.1488463 | I43: =IF(I6=0,"",I42/I6) -> 0.44686698 | ... K43: =IF(K6=0,"",K42/K6) -> 0.44865012
A45: 참고: 세후영업이익 (Memo: NOPAT = EBIT x (1 - t)) | B45: =B9*(1-B40) -> 1527.86 | C45: =C9*(1-C40) -> 2535.9 | D45: =D9*(1-D40) -> 3005.16 | E45: =E9*(1-E40) -> 2248.34 | F45: =F9*(1-F40) -> 3580.28 | G45: =G9*(1-G40) -> 7932.39 | H45: =H9*(1-H40) -> 3336.96 | I45: =I9*(1-I40) -> 26047.88 | ... K45: =K9*(1-K40) -> 103005.73
A46: 참고: NOPAT 방식 FCFF (Memo: FCFF via NOPAT route) | B46: =B45+B18-B17 -> 1538.86 | C46: =C45+C18-C17 -> 2141.9 | D46: =D45+D18-D17 -> 2667.16 | E46: =E45+E18-E17 -> 2140.34 | F46: =F45+F18-F17 -> 3550.28 | G46: =G45+G18-G17 -> 8130.39 | H46: =H45+H18-H17 -> 3047.96 | I46: =I45+I18-I17 -> 26486.88 | ... K46: =K45+K18-K17 -> 99806.73 | M46: 운전자본 증감을 반영하지 않으므로 영업활동현금흐름 방식과 일치하지 않습니다. 그 차이가 곧 운전자본 투자액이며, 슬라이드 한 장으로 다룰 만한 주제입니다.
...

Sheet Raw_SKhynix
A1: SK hynix Inc. — 10개년 FCFF 입력자료
A2: 단위: 십억 원(1,000 = 1조 원). K-IFRS 연결기준, 12월 31일 결산.
A4: 회계연도 (Fiscal year) | B4: 2016 | C4: 2017 | D4: 2018 | E4: 2019 | F4: 2020 | G4: 2021 | H4: 2022 | I4: 2023 | J4: 2024 | K4: 2025 | L4: 등급 (Tier) | M4: 비고 (Note)
A5: 손익계산서
A6: 매출액 (Revenue) | B6: 17198 | C6: 30109 | D6: 40445 | E6: 26991 | F6: 31900 | G6: 42998 | H6: 44648 | I6: 32766 | J6: 66193 | K6: 97147
A7: 매출총이익 (Gross profit) | B7: 5528 | C7: 17164 | D7: 24625 | E7: 7757 | F7: 12470 | G7: 20265 | H7: 16193 | I7: -533 | J7: 31828 | K7: 58691
A8: 판매비와관리비 (Selling & administrative expenses) | B8: 1220 | C8: 1719 | D8: 2003 | E8: 2531 | F8: 3123 | G8: 3529 | H8: 4472 | I8: 3446 | J8: 3924 | K8: 5019
A9: 경상연구개발비 (Research & development expenses) | B9: 1031 | C9: 1724 | D9: 1778 | E9: 2513 | F9: 4221 | G9: 4326 | H9: 4714 | I9: 3751 | J9: 4436 | K9: 6466
A10: 영업이익 (Operating income (EBIT)) | B10: 3277 | C10: 13721 | D10: 20844 | E10: 2713 | F10: 5126 | G10: 12410 | H10: 7007 | I10: -7730 | J10: 23468 | K10: 47206
A11: 이자비용(추정) (Interest expense (approx.)) | M11: SK hynix는 이자비용을 별도 표시하지 않고 금융수익·금융비용으로 보고합니다. 정확한 가산액이 필요하면 DART 주석에서 확인해 입력하십시오.
A12: 법인세비용차감전순이익 (Pre-tax income) | B12: 3646 | C12: 13847 | D12: 21125 | E12: 2665 | F12: 6221 | G12: 12447 | H12: 3406 | I12: -11658 | J12: 23885 | K12: 50466
A13: 법인세비용 (Income tax expense) | B13: 692 | C13: 3205 | D13: 5585 | E13: 649 | F13: 1462 | G13: 2830 | H13: 967 | I13: -2520 | J13: 4088 | K13: 7518
A14: 당기순이익 (Net income) | B14: 2954 | C14: 10642 | D14: 15540 | E14: 2016 | F14: 4759 | G14: 9617 | H14: 2439 | I14: -9138 | J14: 19797 | K14: 42948
A16: 현금흐름표
A17: 영업활동현금흐름 (Cash flow from operations (CFO)) | B17: 5361 | C17: 14944 | D17: 21114 | E17: 12167 | F17: 12335 | G17: 19750 | H17: 14771 | I17: 4278 | J17: 29796 | K17: 53373
A18: 자본적지출 (Capital expenditures) | B18: 6293 | C18: 9569 | D18: 17000 | E18: 12665 | F18: 10100 | G18: 12487 | H18: 19010 | I18: 8325 | J18: 15946 | K18: 27519 | M18: 공시된 자본적지출 항목만 반영 — 투자활동 내 유가증권 취득과 사업결합은 제외.
A19: 감가상각비·무형자산상각비 (Depreciation & amortisation) | B19: 4924 | C19: 5344 | D19: 6613 | E19: 9308 | F19: 10390 | G19: 12040 | H19: 13800 | I19: 13619 | J19: 12545 | K19: 13890
A21: 재무상태표 (기말)
A22: 자산총계 (Total assets) | B22: 32319 | C22: 40289 | D22: 63548 | E22: 71299 | F22: 85284 | G22: 100000 | H22: 103873 | I22: 100330 | J22: 119855 | K22: 176108
A23: 현금및현금성자산 (Cash & cash equivalents) | B23: 1500 | C23: 1800 | D23: 2900 | E23: 2280 | F23: 4477 | G23: 4372 | H23: 4936 | I23: 7587 | J23: 11205 | K23: 14924
A24: 단기차입금 (Short-term borrowings) | B24: 2200 | C24: 1300 | D24: 1900 | E24: 2900 | F24: 3400 | G24: 4200 | H24: 6600 | I24: 9857 | J24: 5252 | K24: 8162
A25: 장기차입금 (Long-term borrowings) | B25: 4500 | C25: 3600 | D25: 4000 | E25: 8800 | F25: 12200 | G25: 16700 | H25: 17100 | I25: 19611 | J25: 17431 | K25: 14086
A26: 총차입금 (Total debt) | B26: =B24+B25 -> 6700 | C26: =C24+C25 -> 4900 | D26: =D24+D25 -> 5900 | E26: =E24+E25 -> 11700 | F26: =F24+F25 -> 15600 | G26: =G24+G25 -> 20900 | H26: =H24+H25 -> 23700 | I26: =I24+I25 -> 29468 | ... K26: =K24+K25 -> 22248
A27: 순차입금(순현금) (Net debt (cash)) | B27: =B26-B23 -> 5200 | C27: =C26-C23 -> 3100 | D27: =D26-D23 -> 3000 | E27: =E26-E23 -> 9420 | F27: =F26-F23 -> 11123 | G27: =G26-G23 -> 16528 | H27: =H26-H23 -> 18764 | I27: =I26-I23 -> 21881 | ... K27: =K26-K23 -> 7324
A28: 자본총계 (Total equity) | B28: 22226 | C28: 31181 | D28: 46512 | E28: 49135 | F28: 53186 | G28: 63125 | H28: 61242 | I28: 53504 | J28: 73916 | K28: 120667
A29: 발행주식수 (Shares outstanding (m)) | B29: 728 | C29: 728 | D29: 728 | E29: 728 | F29: 728 | G29: 728 | H29: 728 | I29: 728 | J29: 728 | K29: 728
A31: 산출 비율 — 전부 수식이며 직접 입력한 값 없음
A32: 매출액 증가율 (Revenue growth) | C32: =IF(B6=0,"",C6/B6-1) -> 0.75072683 | D32: =IF(C6=0,"",D6/C6-1) -> 0.34328606 | E32: =IF(D6=0,"",E6/D6-1) -> -0.33264928 | F32: =IF(E6=0,"",F6/E6-1) -> 0.18187544 | G32: =IF(F6=0,"",G6/F6-1) -> 0.34789969 | H32: =IF(G6=0,"",H6/G6-1) -> 0.038373878 | I32: =IF(H6=0,"",I6/H6-1) -> -0.26612614 | J32: =IF(I6=0,"",J6/I6-1) -> 1.0201734 | K32: =IF(J6=0,"",K6/J6-1) -> 0.46763253
A33: 영업이익률 (Operating margin) | B33: =IF(B6=0,"",B10/B6) -> 0.19054541 | C33: =IF(C6=0,"",C10/C6) -> 0.45571092 | D33: =IF(D6=0,"",D10/D6) -> 0.51536655 | E33: =IF(E6=0,"",E10/E6) -> 0.10051499 | F33: =IF(F6=0,"",F10/F6) -> 0.16068966 | G33: =IF(G6=0,"",G10/G6) -> 0.28861808 | H33: =IF(H6=0,"",H10/H6) -> 0.15693872 | I33: =IF(I6=0,"",I10/I6) -> -0.23591528 | ... K33: =IF(K6=0,"",K10/K6) -> 0.48592339
A34: 순이익률 (Net margin) | B34: =IF(B6=0,"",B14/B6) -> 0.17176416 | C34: =IF(C6=0,"",C14/C6) -> 0.35344913 | D34: =IF(D6=0,"",D14/D6) -> 0.38422549 | E34: =IF(E6=0,"",E14/E6) -> 0.074691564 | F34: =IF(F6=0,"",F14/F6) -> 0.14918495 | G34: =IF(G6=0,"",G14/G6) -> 0.22366157 | H34: =IF(H6=0,"",H14/H6) -> 0.054627307 | I34: =IF(I6=0,"",I14/I6) -> -0.27888665 | ... K34: =IF(K6=0,"",K14/K6) -> 0.44209291
A35: 유효법인세율 (Effective tax rate) | B35: =IFERROR(B13/B12,"") -> 0.18979704 | C35: =IFERROR(C13/C12,"") -> 0.23145808 | D35: =IFERROR(D13/D12,"") -> 0.2643787 | E35: =IFERROR(E13/E12,"") -> 0.2435272 | F35: =IFERROR(F13/F12,"") -> 0.23501045 | G35: =IFERROR(G13/G12,"") -> 0.22736402 | H35: =IFERROR(H13/H12,"") -> 0.28391075 | I35: =IFERROR(I13/I12,"") -> 0.21616058 | ... K35: =IFERROR(K13/K12,"") -> 0.14897158 | M35: 결손 연도에는 음수나 비정상적 값이 나타납니다. 모형에서 정상화 세율을 쓰는 이유입니다.
A36: 자본적지출/매출액 (Capex / revenue) | B36: =IF(B6=0,"",B18/B6) -> 0.36591464 | C36: =IF(C6=0,"",C18/C6) -> 0.31781195 | D36: =IF(D6=0,"",D18/D6) -> 0.4203239 | E36: =IF(E6=0,"",E18/E6) -> 0.46923048 | F36: =IF(F6=0,"",F18/F6) -> 0.31661442 | G36: =IF(G6=0,"",G18/G6) -> 0.29040886 | H36: =IF(H6=0,"",H18/H6) -> 0.42577495 | I36: =IF(I6=0,"",I18/I6) -> 0.25407435 | ... K36: =IF(K6=0,"",K18/K6) -> 0.28327174
A37: 자본적지출/감가상각비 (Capex / D&A) | B37: =IFERROR(B18/B19,"") -> 1.278026 | C37: =IFERROR(C18/C19,"") -> 1.7906063 | D37: =IFERROR(D18/D19,"") -> 2.5706941 | E37: =IFERROR(E18/E19,"") -> 1.3606575 | F37: =IFERROR(F18/F19,"") -> 0.97208855 | G37: =IFERROR(G18/G19,"") -> 1.0371262 | H37: =IFERROR(H18/H19,"") -> 1.3775362 | I37: =IFERROR(I18/I19,"") -> 0.61127836 | ... K37: =IFERROR(K18/K19,"") -> 1.9812095 | M37: 1.0배를 넘으면 자산을 유지하는 수준을 넘어 확장하고 있다는 뜻입니다.
A39: FCFF 산출 — FCFF = 영업활동현금흐름 + 이자비용 x (1 - t) - 자본적지출
A40: 적용 법인세율(정상화) (Normalised tax rate used) | B40: 0.22 | C40: 0.22 | D40: 0.22 | E40: 0.22 | F40: 0.22 | G40: 0.22 | H40: 0.22 | I40: 0.22 | J40: 0.22 | K40: 0.22 | M40: 법정세율에 준하는 값. 자유롭게 수정하십시오. 이자 절세효과가 FCFF를 실제로 얼마나 적게 움직이는지 보여주는 셀입니다.
A41: 이자비용 x (1 - t) (Interest x (1 - t)) | B41: =B11*(1-B40) -> 0 | C41: =C11*(1-C40) -> 0 | D41: =D11*(1-D40) -> 0 | E41: =E11*(1-E40) -> 0 | F41: =F11*(1-F40) -> 0 | G41: =G11*(1-G40) -> 0 | H41: =H11*(1-H40) -> 0 | I41: =I11*(1-I40) -> 0 | ... K41: =K11*(1-K40) -> 0
A42: 기업잉여현금흐름 (FCFF) | B42: =B17+B41-B18 -> -932 | C42: =C17+C41-C18 -> 5375 | D42: =D17+D41-D18 -> 4114 | E42: =E17+E41-E18 -> -498 | F42: =F17+F41-F18 -> 2235 | G42: =G17+G41-G18 -> 7263 | H42: =H17+H41-H18 -> -4239 | I42: =I17+I41-I18 -> -4047 | ... K42: =K17+K41-K18 -> 25854
A43: FCFF 마진 (FCFF margin) | B43: =IF(B6=0,"",B42/B6) -> -0.054192348 | C43: =IF(C6=0,"",C42/C6) -> 0.17851805 | D43: =IF(D6=0,"",D42/D6) -> 0.10171838 | E43: =IF(E6=0,"",E42/E6) -> -0.018450595 | F43: =IF(F6=0,"",F42/F6) -> 0.070062696 | G43: =IF(G6=0,"",G42/G6) -> 0.16891483 | H43: =IF(H6=0,"",H42/H6) -> -0.094942663 | I43: =IF(I6=0,"",I42/I6) -> -0.12351218 | ... K43: =IF(K6=0,"",K42/K6) -> 0.26613277
A45: 참고: 세후영업이익 (Memo: NOPAT = EBIT x (1 - t)) | B45: =B10*(1-B40) -> 2556.06 | C45: =C10*(1-C40) -> 10702.38 | D45: =D10*(1-D40) -> 16258.32 | E45: =E10*(1-E40) -> 2116.14 | F45: =F10*(1-F40) -> 3998.28 | G45: =G10*(1-G40) -> 9679.8 | H45: =H10*(1-H40) -> 5465.46 | I45: =I10*(1-I40) -> -6029.4 | ... K45: =K10*(1-K40) -> 36820.68
A46: 참고: NOPAT 방식 FCFF (Memo: FCFF via NOPAT route) | B46: =B45+B19-B18 -> 1187.06 | C46: =C45+C19-C18 -> 6477.38 | D46: =D45+D19-D18 -> 5871.32 | E46: =E45+E19-E18 -> -1240.86 | F46: =F45+F19-F18 -> 4288.28 | G46: =G45+G19-G18 -> 9232.8 | H46: =H45+H19-H18 -> 255.46 | I46: =I45+I19-I18 -> -735.4 | ... K46: =K45+K19-K18 -> 23191.68 | M46: 운전자본 증감을 반영하지 않으므로 영업활동현금흐름 방식과 일치하지 않습니다. 그 차이가 곧 운전자본 투자액이며, 슬라이드 한 장으로 다룰 만한 주제입니다.
...

Sheet Raw_Quarterly
A1: 최근 분기 실적
A2: 분기말 재무상태표가 공시된 경우에만 재무상태표 항목을 표시했습니다.
A4: NVIDIA (분기)
A5: 단위: 백만 달러
A6: 분기 (Quarter) | B6: 매출액 (Revenue) | C6: 영업이익 (Operating income) | D6: 당기순이익 (Net income) | E6: 영업활동현금흐름 (CFO) | F6: 자본적지출 (Capex) | G6: 자산총계 (Total assets) | H6: 현금및유가증권 (Cash & securities) | I6: 총차입금 (Total debt) | J6: 자본총계 (Total equity) | K6: 등급 (Tier)
A7: Q1 FY26 (Apr-2025) | B7: 44062 | C7: 21638 | D7: 18775 | E7: 27414 | F7: 1227 | K7: A
A8: Q2 FY26 (Jul-2025) | B8: 46743 | C8: 28442 | D8: 26422 | E8: 15359 | F8: 1470 | K8: C
A9: Q3 FY26 (Oct-2025) | B9: 57006 | C9: 36010 | D9: 31910 | E9: 23750 | F9: 1637 | K9: A
A10: Q4 FY26 (Jan-2026) | B10: 68127 | C10: 44299 | D10: 42960 | E10: 36190 | F10: 1284 | G10: 206803 | H10: 62556 | I10: 8468 | J10: 157293 | K10: A
A11: Q1 FY27 (Apr-2026) | B11: 81615 | C11: 53536 | D11: 58321 | E11: 50344 | F11: 1757 | G11: 259474 | H11: 80572 | I11: 8470 | J11: 195474 | K11: A
A13: 분기별 영업이익률 (Operating margin by quarter)
A14: Q1 FY26 (Apr-2025) | B14: =IF(B7=0,"",C7/B7) -> 0.49108075
A15: Q2 FY26 (Jul-2025) | B15: =IF(B8=0,"",C8/B8) -> 0.60847614
A16: Q3 FY26 (Oct-2025) | B16: =IF(B9=0,"",C9/B9) -> 0.63168789
A17: Q4 FY26 (Jan-2026) | B17: =IF(B10=0,"",C10/B10) -> 0.65024146
A18: Q1 FY27 (Apr-2026) | B18: =IF(B11=0,"",C11/B11) -> 0.65595785
A21: SK hynix (분기)
A22: 단위: 십억 원
A23: 분기 (Quarter) | B23: 매출액 (Revenue) | C23: 영업이익 (Operating income) | D23: 당기순이익 (Net income) | E23: 영업활동현금흐름 (CFO) | F23: 자본적지출 (Capex) | G23: 자산총계 (Total assets) | H23: 현금및현금성자산 (Cash & equivalents) | I23: 차입금 합계 (Total borrowings) | J23: 자본총계 (Total equity) | K23: 등급 (Tier)
A24: Q1 2025 (Mar-2025) | B24: 17639 | C24: 7441 | D24: 8108 | E24: 9024 | F24: 6284 | K24: A
A25: Q2 2025 (Jun-2025) | B25: 22232 | C25: 9213 | D25: 6995 | K25: B
A26: Q3 2025 (Sep-2025) | B26: 24449 | C26: 11383 | D26: 12598 | K26: B
A27: Q4 2025 (Dec-2025) | B27: 32827 | C27: 19170 | D27: 15246 | G27: 176108 | H27: 14924 | I27: 22248 | J27: 120667 | K27: B
A28: Q1 2026 (Mar-2026) | B28: 52576 | C28: 37610 | D28: 40346 | E28: 26330 | F28: 7657 | G28: 222829 | H28: 21167 | I28: 19318 | J28: 164380 | K28: A
A29: Q2 2026 (Jun-2026) | B29: 79319 | C29: 60543 | D29: 93923 | H29: 88000 | I29: 18600 | K29: B
A31: 분기별 영업이익률 (Operating margin by quarter)
A32: Q1 2025 (Mar-2025) | B32: =IF(B24=0,"",C24/B24) -> 0.42184931
A33: Q2 2025 (Jun-2025) | B33: =IF(B25=0,"",C25/B25) -> 0.41440266
A34: Q3 2025 (Sep-2025) | B34: =IF(B26=0,"",C26/B26) -> 0.46558141
A35: Q4 2025 (Dec-2025) | B35: =IF(B27=0,"",C27/B27) -> 0.58397051
A36: Q1 2026 (Mar-2026) | B36: =IF(B28=0,"",C28/B28) -> 0.7153454
A37: Q2 2026 (Jun-2026) | B37: =IF(B29=0,"",C29/B29) -> 0.76328496
A39: 참고: SK hynix의 2026년 2분기 당기순이익 93,923십억 원이 매출액 79,319십억 원을 초과하는 것은 Kioxia 지분 매각에 따른 투자자산 처분이익 약 63조 원이 포함되었기 때문입니다. FCFF는 당기순이익이 아니라 영업이익에서 출발해야 합니다.
A43: past 60 quarters total assets, cash, inventory, total debt, , totoal revenue, opearting income, net income, cash flows, from operations (CFO), cash flows from investing, capital expenditures, interest expense, effective tax rate, FCFF (free cash flows to firm), which is defined as *CFO + (Interest Expense x (1-tax rate) - capital expenditures for skynix

Sheet Consensus
A1: 증권사 컨센서스 — 기업 단위
A2: 2026년 8월 5일 수집.
A4: SK hynix
A5: 항목 (Metric) | B5: 단위 (Unit) | C5: 값 (Value) | D5: 출처 / 유의사항 (Source / caveat)
A6: 2026년 2분기 매출액(추정) (Q2 2026 revenue (est.)) | B6: 조 원 (KRW tn) | C6: 84 | D6: 실적 발표 전 LSEG SmartEstimates 기준, 실제치는 79.3조 원
A7: 2026년 2분기 영업이익(추정) (Q2 2026 op. profit (est.)) | B7: 조 원 (KRW tn) | C7: 64.1 | D7: 연합인포맥스, 증권사 14곳 기준, 실제치는 60.5조 원
A8: 2026년 영업이익 (FY2026 operating profit) | B8: 조 원 (KRW tn) | C8: 99 | D8: Nomura 추정치 (단일 증권사, 컨센서스 아님)
A9: 2027년 영업이익 (FY2027 operating profit) | B9: 조 원 (KRW tn) | C9: 128 | D9: Nomura 추정치 (단일 증권사, 컨센서스 아님)
A10: 2026년 자본적지출 (FY2026 capex) | B10: 조 원 (KRW tn) | C10: 45 | D10: 회사 가이던스: 40조 원대 후반
A11: 12개월 목표주가 (12-mo price target) | B11: 원 (KRW) | C11: 3189340 | D11: 애널리스트 37명 평균(Investing.com)
A13: FCFF 추정치에 관하여
A14: 두 기업 모두 기업 단위 FCFF에 대한 증권사 컨센서스는 공표되지 않습니다. 컨센서스는 매출액, 주당순이익,
A15: 강의 목적으로는 컨센서스 매출액과 영업이익률 경로를 출발점으로 삼고, 학생들이 여기에 자본적지출과 운전자본을 더해 FCFF를 직접 구성하도록 하는 편이 낫습니다. 추정은 증권사가 아니라 학생 자신의 것이어야 한다는 점이 이 실습의 핵심입니다.
A16: 확인한 공개 자료에는 SK hynix의 2026년·2027년 영업이익 컨센서스가 존재하지 않습니다. 위의 Nomura 수치는 단일 증권사 추정치이며 그렇게 표기했습니다.

Sheet 1) DCF Val_FCFF
A1: SK hynix — FCFF 현금흐름할인법
A2: 단위: 십억 원(주당 금액 제외). 기준연도 = 2025년(2025년 12월 31일 종료).
A4: 1. 시장 데이터 (파란색 = 수업 전 업데이트)
A5: 주가 (Share price) | B5: 1577000 | L5: 기준일: 2026-08-04
A6: 희석 발행주식수 (Diluted shares outstanding (m)) | B6: 730.49
A7: 단위 환산계수 (Units scalar (statement unit per share unit)) | B7: 1000 | L7: 재무제표는 십억 원, 주식수는 백만 주, 주가는 원 단위이므로 주당가치를 구하려면 자기자본가치에 1,000을 곱해야 합니다.
A8: 시가총액 (Market capitalisation) | B8: =B5*B6/B7 -> 1151982.7 | L8: 위 재무제표와 동일한 단위로 표시했습니다.
A9: 총차입금(최근 재무상태표) (Total debt (latest balance sheet)) | B9: 18600
A10: 현금및유가증권 (Cash & marketable securities) | B10: 88000
A11: 기타 비영업투자자산 (Other non-operating investments) | B11: 20658 | L11: 비시장성 유가증권 및 장기투자자산. 자기자본가치 조정 단계에서 가산합니다.
A12: 비유동리스부채 (Non-current lease liabilities) | B12: 1988 | L12: 차입금 성격의 부채. 자기자본가치 조정 단계에서 차감합니다.
A14: 2. 자본비용
A15: 무위험이자율 (Risk-free rate) | B15: 0.03 | L15: 한국 10년 국고채 수익률 근사치. 강의 당일 업데이트하십시오.
A16: 시장위험프리미엄 (Equity risk premium) | B16: 0.06 | L16: 선진시장 시장위험프리미엄에 한국 국가위험프리미엄을 가산한 값입니다.
A17: 레버드 베타 (Levered equity beta) | B17: 1.76 | L17: 000660의 공표 베타(TradingView). 메모리는 베타가 높은 경기민감 업종입니다.
A18: 자기자본비용 (Cost of equity (CAPM)) | B18: =B15+B17*B16 -> 0.1356 | L18: ke = 무위험이자율 + 베타 x 시장위험프리미엄
A19: 세전 타인자본비용 (Pre-tax cost of debt) | B19: 0.045 | L19: SK hynix는 큰 폭의 순현금 상태이므로 이 값의 영향은 매우 작습니다.
A20: 한계법인세율 (Marginal tax rate) | B20: 0.22 | L20: 지방소득세를 포함한 한국 법정 법인세율 근사치입니다.
A21: 세후 타인자본비용 (After-tax cost of debt) | B21: =B19*(1-B20) -> 0.0351
A22: 자기자본 비중 E/(D+E) (Weight of equity E/(D+E)) | B22: =B8/(B8+B9) -> 0.98411048
A23: 타인자본 비중 D/(D+E) (Weight of debt D/(D+E)) | B23: =B9/(B8+B9) -> 0.015889522
A24: 가중평균자본비용 (WACC) | B24: =B22*B18+B23*B21 -> 0.1340031 | L24: 시장가치 기준 가중치입니다. 두 기업 모두 순차입금이 0에 가까워 WACC가 자기자본비용과 거의 같아집니다. 이 사례에서 자본구조 논의가 큰 의미를 갖지 못하는 이유이므로 수업에서 명시적으로 짚어주시기 바랍니다.
A26: 3. FCFF 추정
A27: 연도 (Year) | C27: 기준연도(최근) (Base (latest)) | D27: +1 | E27: +2 | F27: +3 | G27: +4 | H27: +5 | I27: 영구 (Terminal)
A28: 매출액 증가율 (Revenue growth) | D28: 1.85 | E28: 0.15 | F28: -0.25 | G28: 0.05 | H28: 0.05 | L28: 모형에서 가장 영향이 큰 변수입니다.
A29: 매출액 (Revenue) | C29: =Raw_SKhynix!K6 -> 97147 | D29: =C29*(1+D28) -> 276868.95 | E29: =D29*(1+E28) -> 318399.29 | F29: =E29*(1+F28) -> 238799.47 | G29: =F29*(1+G28) -> 250739.44 | H29: =G29*(1+H28) -> 263276.41
A30: 영업이익률 (Operating margin) | C30: =IFERROR(Raw_SKhynix!K10/Raw_SKhynix!K6,"") -> 0.48592339 | D30: 0.72 | E30: 0.62 | F30: 0.35 | G30: 0.35 | H30: 0.34
A31: 영업이익 (EBIT) | C31: =C29*C30 -> 47206 | D31: =D29*D30 -> 199345.64 | E31: =E29*E30 -> 197407.56 | F31: =F29*F30 -> 83579.814 | G31: =G29*G30 -> 87758.805 | H31: =H29*H30 -> 89513.981
A32: 차감: 영업이익에 대한 법인세 (less: tax on EBIT) | C32: =-C31*B20 -> -10385.32 | D32: =-D31*B20 -> -43856.042 | E32: =-E31*B20 -> -43429.663 | F32: =-F31*B20 -> -18387.559 | G32: =-G31*B20 -> -19306.937 | H32: =-H31*B20 -> -19693.076
A33: 세후영업이익 (NOPAT) | C33: =C31+C32 -> 36820.68 | D33: =D31+D32 -> 155489.6 | E33: =E31+E32 -> 153977.9 | F33: =F31+F32 -> 65192.255 | G33: =G31+G32 -> 68451.868 | H33: =H31+H32 -> 69820.905
A34: 가산: 감가상각비(매출액 대비) (plus: D&A (% of revenue)) | C34: =IFERROR(Raw_SKhynix!K19/Raw_SKhynix!K6,"") -> 0.1429792 | D34: 0.13 | E34: 0.13 | F34: 0.13 | G34: 0.13 | H34: 0.13
A35: 감가상각비 (D&A) | C35: =C29*C34 -> 13890 | D35: =D29*D34 -> 35992.964 | E35: =E29*E34 -> 41391.908 | F35: =F29*F34 -> 31043.931 | G35: =G29*G34 -> 32596.128 | H35: =H29*H34 -> 34225.934
A36: 차감: 자본적지출(매출액 대비) (less: capex (% of revenue)) | C36: =IFERROR(Raw_SKhynix!K18/Raw_SKhynix!K6,"") -> 0.28327174 | D36: 0.3 | E36: 0.28 | F36: 0.26 | G36: 0.24 | H36: 0.22 | L36: 영구성장 구간에서는 자본적지출이 감가상각비 수준으로 수렴해야 합니다. 그렇지 않으면 투자 없이 영원히 성장하는 기업이 됩니다.
A37: 자본적지출 (Capex) | C37: =-C29*C36 -> -27519 | D37: =-D29*D36 -> -83060.685 | E37: =-E29*E36 -> -89151.802 | F37: =-F29*F36 -> -62087.862 | G37: =-G29*G36 -> -60177.466 | H37: =-H29*H36 -> -57920.811
A38: 차감: 운전자본 증가 (less: increase in working capital) | D38: 0.15 | E38: 0.15 | F38: 0.15 | G38: 0.15 | H38: 0.15 | L38: 매출액 증감액 대비 비율입니다. 메모리와 GPU 사이클은 운전자본 소요가 큽니다. 원자료 탭에서 재고자산과 매출채권 증가율을 확인하십시오.
A39: 운전자본 증감 (Change in working capital) | D39: =-(D29-C29)*D38 -> -26958.292 | E39: =-(E29-D29)*E38 -> -6229.5514 | F39: =-(F29-E29)*F38 -> 11939.973 | G39: =-(G29-F29)*G38 -> -1790.996 | H39: =-(H29-G29)*H38 -> -1880.5458
A40: 기업잉여현금흐름 (FCFF) | C40: =Raw_SKhynix!K42 -> 25854 | D40: =D33+D35+D37+D39 -> 81463.588 | E40: =E33+E35+E37+E39 -> 99988.453 | F40: =F33+F35+F37+F39 -> 46088.298 | G40: =G33+G35+G37+G39 -> 39079.533 | H40: =H33+H35+H37+H39 -> 44245.482
A41: 참고: FCFF 마진 (memo: FCFF margin) | C41: =IFERROR(C40/C29,"") -> 0.26613277 | D41: =IFERROR(D40/D29,"") -> 0.29423158 | E41: =IFERROR(E40/E29,"") -> 0.31403478 | F41: =IFERROR(F40/F29,"") -> 0.193 | G41: =IFERROR(G40/G29,"") -> 0.15585714 | H41: =IFERROR(H40/H29,"") -> 0.16805714
A43: 4. 할인 및 기업가치 산정
A44: 영구성장률 (Terminal growth rate) | B44: 0.025 | L44: 장기 명목 GDP 성장률보다 낮아야 합니다. WACC를 넘으면 공식이 성립하지 않습니다.
...

Sheet 2) VAL with Earnings
A1: SK hynix — DCF Model - Inputs replaced by Earnings
A2: 단위: 십억 원(주당 금액 제외). 기준연도 = 2025년(2025년 12월 31일 종료).
A4: 1. 시장 데이터 (파란색 = 수업 전 업데이트)
A5: 주가 (Share price) | B5: 1577000
A6: 희석 발행주식수 (Diluted shares outstanding (m)) | B6: 730.49
A7: 단위 환산계수 (Units scalar (statement unit per share unit)) | B7: 1000
A8: 시가총액 (Market capitalisation) | B8: =B5*B6/B7 -> 1151982.7
A14: 2. 자본비용
A15: 무위험이자율 (Risk-free rate) | B15: 0.03
A16: 시장위험프리미엄 (Equity risk premium) | B16: 0.06
A17: 레버드 베타 (Levered equity beta) | B17: 1.76
A18: 자기자본비용 (Cost of equity (CAPM)) | B18: =B15+B17*B16 -> 0.1356
A24: 가중평균자본비용 (WACC) | B24: =B18 -> 0.1356
A26: 3. FCFF 추정
A27: 연도 (Year) | C27: 기준연도(최근) (Base (latest)) | D27: +1 | E27: +2 | F27: +3 | G27: +4 | H27: +5 | I27: 영구 (Terminal)
A28: 매출액 증가율 (Revenue growth) | D28: 1.85 | E28: 0.15 | F28: -0.25 | G28: 0.05 | H28: 0.05
A29: 영업이익 | C29: =Raw_SKhynix!K6 -> 97147 | D29: =C29*(1+D28) -> 276868.95 | E29: =D29*(1+E28) -> 318399.29 | F29: =E29*(1+F28) -> 238799.47 | G29: =F29*(1+G28) -> 250739.44 | H29: =G29*(1+H28) -> 263276.41
A30: 영업이익률 (Operating margin) | C30: =IFERROR(Raw_SKhynix!K10/Raw_SKhynix!K6,"") -> 0.48592339 | D30: 0.72 | E30: 0.62 | F30: 0.35 | G30: 0.35 | H30: 0.34
A31: 영업이익 (EBIT) | C31: =C29*C30 -> 47206 | D31: =D29*D30 -> 199345.64 | E31: =E29*E30 -> 197407.56 | F31: =F29*F30 -> 83579.814 | G31: =G29*G30 -> 87758.805 | H31: =H29*H30 -> 89513.981
A40: Valuation Model - 분자 | C40: =C31 -> 47206 | D40: =D31 -> 199345.64 | E40: =E31 -> 197407.56 | F40: =F31 -> 83579.814 | G40: =G31 -> 87758.805 | H40: =H31 -> 89513.981
A42: 4. 할인 및 기업가치 산정
A43: 영구성장률 (Terminal growth rate) | B43: 0.025
A44: 현가계수 (Discount factor) | D44: =1/(1+B24)^1 -> 0.88059176 | E44: =1/(1+B24)^2 -> 0.77544184 | F44: =1/(1+B24)^3 -> 0.6828477 | G44: =1/(1+B24)^4 -> 0.60131005 | H44: =1/(1+B24)^5 -> 0.52950868
A45: FCFF 현재가치 (PV of FCFF) | D45: =D40*D44 -> 175542.13 | E45: =E40*E44 -> 153078.08 | F45: =F40*F44 -> 57072.284 | G45: =G40*G44 -> 52770.252 | H45: =H40*H44 -> 47398.43
A46: 명시적 예측기간 현재가치 합계 (Sum of PV, explicit period) | B46: =SUM(D45:H45) -> 485861.18
A47: 5차연도 영구가치 (Terminal value at year 5) | B47: =H40*(1+B43)/(B24-B43) -> 829582.56
A48: 영구가치의 현재가치 (PV of terminal value) | B48: =B47/(1+B24)^5 -> 439271.16
A49: 영구가치가 기업가치에서 차지하는 비중 (Terminal value as % of EV) | B49: =IFERROR(B48/(B48+B46),"") -> 0.47481981
A50: 기업가치 (ENTERPRISE VALUE) | B50: =B46+B48 -> 925132.34
A52: 5. 자기자본가치 조정 — 기업가치에서 주당가치까지
A53: 기업가치(영업자산) (Enterprise value (operating assets)) | B53: =B50 -> 925132.34
A58: 자기자본가치 (EQUITY VALUE) | B58: =SUM(B53:B57) -> 925132.34
A59: 발행주식수 (Shares outstanding (m)) | B59: =B6 -> 730.49
A60: 주당가치 (VALUE PER SHARE) | B60: =B58*B7/B6 -> 1266454.5
A61: 현재 주가 (Current share price) | B61: =B5 -> 1577000
A62: 상승여력/(하락위험) (Upside / (downside)) | B62: =IFERROR(B60/B5-1,"") -> -0.19692169

Sheet 3) VAL Gordon Growth Model
A1: SK hynix — P/E = 1/(r-g) Model
A2: 단위: 십억 원(주당 금액 제외). 기준연도 = 2025년(2025년 12월 31일 종료).
A4: 1. 시장 데이터 (파란색 = 수업 전 업데이트)
A5: 주가 (Share price) | B5: 1577000
A6: 희석 발행주식수 (Diluted shares outstanding (m)) | B6: 730.49
A7: 단위 환산계수 (Units scalar (statement unit per share unit)) | B7: 1000
A8: 시가총액 (Market capitalisation) | B8: =B5*B6/B7 -> 1151982.7
A14: 2. 자본비용
A15: 무위험이자율 (Risk-free rate) | B15: 0.03
A16: 시장위험프리미엄 (Equity risk premium) | B16: 0.06
A17: 레버드 베타 (Levered equity beta) | B17: 1.76
A18: 자기자본비용 (Cost of equity (CAPM)) | B18: =B15+B17*B16 -> 0.1356
A24: 가중평균자본비용 (WACC) | B24: =B18 -> 0.1356
A26: 3. FCFF 추정
A27: 연도 (Year) | C27: 기준연도(최근) (Base (latest)) | D27: +1 | E27: +2 | F27: +3 | G27: +4 | H27: +5 | I27: 영구 (Terminal)
A28: 매출액 증가율 (Revenue growth) | D28: 1.85
A29: 영업이익 | C29: =Raw_SKhynix!K6 -> 97147 | D29: =C29*(1+D28) -> 276868.95
A31: P= E1 / (r-g)
A32: 기업가치(영업자산) (Enterprise value (operating assets)) | C32: =D29/(B18-B43) -> 2503335.9
A40: Valuation Model - 분자 | C40: =C31 -> 0 | D40: =D31 -> 0 | E40: =E31 -> 0 | F40: =F31 -> 0 | G40: =G31 -> 0 | H40: =H31 -> 0
A42: 4. 할인 및 기업가치 산정
A43: 영구성장률 (Terminal growth rate) | B43: 0.025
A50: 기업가치 (ENTERPRISE VALUE) | B50: =C32 -> 2503335.9
A52: 5. 자기자본가치 조정 — 기업가치에서 주당가치까지
A53: 기업가치(영업자산) (Enterprise value (operating assets)) | B53: =B50 -> 2503335.9
A58: 자기자본가치 (EQUITY VALUE) | B58: =SUM(B53:B57) -> 2503335.9
A59: 발행주식수 (Shares outstanding (m)) | B59: =B6 -> 730.49
A60: 주당가치 (VALUE PER SHARE) | B60: =B58*B7/B6 -> 3426927
A61: 현재 주가 (Current share price) | B61: =B5 -> 1577000
A62: 상승여력/(하락위험) (Upside / (downside)) | B62: =IFERROR(B60/B5-1,"") -> 1.1730672
